Workbook

Sheet 当日早見表
A1: 日付を入力 → | B1: =TEXT(TODAY(),"yyyy-mm-dd") | C1: ←TODAY()で自動更新。固定日にしたい場合はyyyy-mm-dd文字列で上書き
A2: 曜日 | B2: =IFERROR(INDEX(早見表_全期間!$B$2:$B$267,MATCH($B$1,早見表_全期間!$A$2:$A$267,0)),"該当なし")
A3: ダイヤ区分 | B3: =IFERROR(INDEX(早見表_全期間!$C$2:$C$267,MATCH($B$1,早見表_全期間!$A$2:$A$267,0)),"該当なし")
A4: 祝日名 | B4: =IFERROR(INDEX(早見表_全期間!$D$2:$D$267,MATCH($B$1,早見表_全期間!$A$2:$A$267,0))&"","")
A6: 系統 | B6: 担当運転士
A7: 1系統 | B7: =IFERROR(INDEX(早見表_全期間!$A$1:$AP$267,MATCH($B$1,早見表_全期間!$A$1:$A$267,0),MATCH($A7,早見表_全期間!$A$1:$AP$1,0)),"-")
A8: 休日前1系統 | B8: =IFERROR(INDEX(早見表_全期間!$A$1:$AP$267,MATCH($B$1,早見表_全期間!$A$1:$A$267,0),MATCH($A8,早見表_全期間!$A$1:$AP$1,0)),"-")
A9: 休日後1系統 | B9: =IFERROR(INDEX(早見表_全期間!$A$1:$AP$267,MATCH($B$1,早見表_全期間!$A$1:$A$267,0),MATCH($A9,早見表_全期間!$A$1:$AP$1,0)),"-")
A10: 2系統 | B10: =IFERROR(INDEX(早見表_全期間!$A$1:$AP$267,MATCH($B$1,早見表_全期間!$A$1:$A$267,0),MATCH($A10,早見表_全期間!$A$1:$AP$1,0)),"-")
A11: 休日前2系統 | B11: =IFERROR(INDEX(早見表_全期間!$A$1:$AP$267,MATCH($B$1,早見表_全期間!$A$1:$A$267,0),MATCH($A11,早見表_全期間!$A$1:$AP$1,0)),"-")
A12: 休日後2系統 | B12: =IFERROR(INDEX(早見表_全期間!$A$1:$AP$267,MATCH($B$1,早見表_全期間!$A$1:$A$267,0),MATCH($A12,早見表_全期間!$A$1:$AP$1,0)),"-")
A13: 3系統 | B13: =IFERROR(INDEX(早見表_全期間!$A$1:$AP$267,MATCH($B$1,早見表_全期間!$A$1:$A$267,0),MATCH($A13,早見表_全期間!$A$1:$AP$1,0)),"-")
A14: 休日前3系統 | B14: =IFERROR(INDEX(早見表_全期間!$A$1:$AP$267,MATCH($B$1,早見表_全期間!$A$1:$A$267,0),MATCH($A14,早見表_全期間!$A$1:$AP$1,0)),"-")
A15: 休日後3系統 | B15: =IFERROR(INDEX(早見表_全期間!$A$1:$AP$267,MATCH($B$1,早見表_全期間!$A$1:$A$267,0),MATCH($A15,早見表_全期間!$A$1:$AP$1,0)),"-")
A16: 4系統 | B16: =IFERROR(INDEX(早見表_全期間!$A$1:$AP$267,MATCH($B$1,早見表_全期間!$A$1:$A$267,0),MATCH($A16,早見表_全期間!$A$1:$AP$1,0)),"-")
A17: 休日前4系統 | B17: =IFERROR(INDEX(早見表_全期間!$A$1:$AP$267,MATCH($B$1,早見表_全期間!$A$1:$A$267,0),MATCH($A17,早見表_全期間!$A$1:$AP$1,0)),"-")
A18: 休日後4系統 | B18: =IFERROR(INDEX(早見表_全期間!$A$1:$AP$267,MATCH($B$1,早見表_全期間!$A$1:$A$267,0),MATCH($A18,早見表_全期間!$A$1:$AP$1,0)),"-")
... A44: 27系統 | B44: =IFERROR(INDEX(早見表_全期間!$A$1:$AP$267,MATCH($B$1,早見表_全期間!$A$1:$A$267,0),MATCH($A44,早見表_全期間!$A$1:$AP$1,0)),"-")

Sheet 早見表_全期間
A1: 日付 | B1: 曜日 | C1: ダイヤ区分 | D1: 祝日名 | E1: 1系統 | F1: 休日前1系統 | G1: 休日後1系統 | H1: 2系統 | I1: 休日前2系統 | J1: 休日後2系統 | K1: 3系統 | L1: 休日前3系統 | M1: 休日後3系統 | N1: 4系統 | O1: 休日前4系統 | P1: 休日後4系統 | Q1: 5系統 | R1: 休日前5系統 | S1: 休日後5系統 | T1: 6系統 | U1: 休日後6系統 | V1: 7系統 | W1: 8系統 | X1: 9系統 | Y1: 10系統 | Z1: 11系統 | AA1: 12系統 | AB1: 13系統 | AC1: 14系統 | AD1: 15系統 | AE1: 16系統 | AF1: 17系統 | AG1: 18系統 | AH1: 19系統 | AI1: 20系統 | AJ1: 21系統 | AK1: 22系統 | AL1: 23系統 | AM1: 24系統 | AN1: 25系統 | AO1: 26系統 | AP1: 27系統
A2: 2026-05-05 | B2: 火 | C2: 休日 | D2: こどもの日 | E2: 中村 | F2: 大川内 | G2: 馬場 | H2: 横田 | I2: 栗下 | J2: 岩田 | K2: 富島 | L2: 安村 | M2: 田中 | N2: 欠員① | O2: 北川 | P2: 丸田 | Q2: 山田久 | R2: 山本高 | S2: 岡本 | T2: 矢田 | U2: 佐野 | V2: 尾川 | W2: 上田 | X2: 河野 | Y2: 植山 | Z2: 柴田 | AA2: 山田真 | AB2: 藤原 | AC2: 井川 | AD2: 谷川 | AE2: 原 | AF2: 中嶌 | AG2: 山本幸 | AH2: 門谷 | AI2: 欠員② | AJ2: 野口 | AK2: 中山 | AL2: 横山 | AM2: 市田 | AN2: 西村 | AO2: 内野 | AP2: 上野
A3: 2026-05-06 | B3: 水 | C3: 休日 | D3: 憲法記念日 振替休日 | E3: 岡本 | F3: 田中 | G3: 尾川 | H3: 北川 | I3: 西村 | J3: 上田 | K3: 中嶌 | L3: 丸田 | M3: 井川 | N3: 山本高 | O3: 河野 | P3: 中山 | Q3: 安村 | R3: 山田真 | S3: 横山 | T3: 佐野 | U3: 上野 | V3: 門谷 | W3: 原 | X3: 富島 | Y3: 野口 | Z3: 藤原 | AA3: 市田 | AB3: 岩田 | AC3: 内野 | AD3: 馬場 | AE3: 横田 | AF3: 大川内 | AG3: 欠員① | AH3: 山田久 | AI3: 矢田 | AJ3: 栗下 | AK3: 欠員② | AL3: 植山 | AM3: 谷川 | AN3: 山本幸 | AO3: 中村 | AP3: 柴田
A4: 2026-05-07 | B4: 木 | C4: 平日 | E4: 横山 | F4: 井川 | G4: 門谷 | H4: 河野 | I4: 山本幸 | J4: 原 | K4: 大川内 | L4: 中山 | M4: 内野 | N4: 山田真 | O4: 富島 | P4: 欠員② | Q4: 丸田 | R4: 市田 | S4: 植山 | T4: 上野 | U4: 柴田 | V4: 山田久 | W4: 横田 | X4: 中嶌 | Y4: 栗下 | Z4: 岩田 | AA4: 谷川 | AB4: 上田 | AC4: 中村 | AD4: 尾川 | AE4: 北川 | AF4: 田中 | AG4: 山本高 | AH4: 安村 | AI4: 佐野 | AJ4: 西村 | AK4: 矢田 | AL4: 野口 | AM4: 馬場 | AN4: 欠員① | AO4: 岡本 | AP4: 藤原
A5: 2026-05-08 | B5: 金 | C5: 平日 | E5: 植山 | F5: 内野 | G5: 山田久 | H5: 富島 | I5: 欠員① | J5: 横田 | K5: 田中 | L5: 欠員② | M5: 中村 | N5: 市田 | O5: 中嶌 | P5: 矢田 | Q5: 中山 | R5: 谷川 | S5: 野口 | T5: 柴田 | U5: 藤原 | V5: 安村 | W5: 北川 | X5: 大川内 | Y5: 西村 | Z5: 上田 | AA5: 馬場 | AB5: 原 | AC5: 岡本 | AD5: 門谷 | AE5: 河野 | AF5: 井川 | AG5: 山田真 | AH5: 丸田 | AI5: 上野 | AJ5: 山本幸 | AK5: 佐野 | AL5: 栗下 | AM5: 尾川 | AN5: 山本高 | AO5: 横山 | AP5: 岩田
A6: 2026-05-09 | B6: 土 | C6: 休日 | E6: 野口 | F6: 中村 | G6: 安村 | H6: 中嶌 | I6: 山本高 | J6: 北川 | K6: 井川 | L6: 矢田 | M6: 岡本 | N6: 谷川 | O6: 大川内 | P6: 佐野 | Q6: 欠員② | R6: 馬場 | S6: 栗下 | T6: 藤原 | U6: 岩田 | V6: 丸田 | W6: 河野 | X6: 田中 | Y6: 山本幸 | Z6: 原 | AA6: 尾川 | AB6: 横田 | AC6: 横山 | AD6: 山田久 | AE6: 富島 | AF6: 内野 | AG6: 市田 | AH6: 中山 | AI6: 柴田 | AJ6: 欠員① | AK6: 上野 | AL6: 西村 | AM6: 門谷 | AN6: 山田真 | AO6: 植山 | AP6: 上田
A7: 2026-05-10 | B7: 日 | C7: 休日 | E7: 栗下 | F7: 岡本 | G7: 丸田 | H7: 大川内 | I7: 山田真 | J7: 河野 | K7: 内野 | L7: 佐野 | M7: 横山 | N7: 馬場 | O7: 田中 | P7: 上野 | Q7: 矢田 | R7: 尾川 | S7: 西村 | T7: 岩田 | U7: 上田 | V7: 中山 | W7: 富島 | X7: 井川 | Y7: 欠員① | Z7: 横田 | AA7: 門谷 | AB7: 北川 | AC7: 植山 | AD7: 安村 | AE7: 中嶌 | AF7: 中村 | AG7: 谷川 | AH7: 欠員② | AI7: 藤原 | AJ7: 山本高 | AK7: 柴田 | AL7: 山本幸 | AM7: 山田久 | AN7: 市田 | AO7: 野口 | AP7: 原
A8: 2026-05-11 | B8: 月 | C8: 平日 | E8: 西村 | F8: 横山 | G8: 中山 | H8: 田中 | I8: 市田 | J8: 富島 | K8: 中村 | L8: 上野 | M8: 植山 | N8: 尾川 | O8: 井川 | P8: 柴田 | Q8: 佐野 | R8: 門谷 | S8: 山本幸 | T8: 上田 | U8: 原 | V8: 欠員② | W8: 中嶌 | X8: 内野 | Y8: 山本高 | Z8: 北川 | AA8: 山田久 | AB8: 河野 | AC8: 野口 | AD8: 丸田 | AE8: 大川内 | AF8: 岡本 | AG8: 馬場 | AH8: 矢田 | AI8: 岩田 | AJ8: 山田真 | AK8: 藤原 | AL8: 欠員① | AM8: 安村 | AN8: 谷川 | AO8: 栗下 | AP8: 横田
A9: 2026-05-12 | B9: 火 | C9: 平日 | E9: 山本幸 | F9: 植山 | G9: 欠員② | H9: 井川 | I9: 谷川 | J9: 中嶌 | K9: 岡本 | L9: 柴田 | M9: 野口 | N9: 門谷 | O9: 内野 | P9: 藤原 | Q9: 上野 | R9: 山田久 | S9: 欠員① | T9: 原 | U9: 横田 | V9: 矢田 | W9: 大川内 | X9: 中村 | Y9: 山田真 | Z9: 河野 | AA9: 安村 | AB9: 富島 | AC9: 栗下 | AD9: 中山 | AE9: 田中 | AF9: 横山 | AG9: 尾川 | AH9: 佐野 | AI9: 上田 | AJ9: 市田 | AK9: 岩田 | AL9: 山本高 | AM9: 丸田 | AN9: 馬場 | AO9: 西村 | AP9: 北川
A10: 2026-05-13 | B10: 水 | C10: 平日 | E10: 欠員① | F10: 野口 | G10: 矢田 | H10: 内野 | I10: 馬場 | J10: 大川内 | K10: 横山 | L10: 藤原 | M10: 栗下 | N10: 山田久 | O10: 中村 | P10: 岩田 | Q10: 柴田 | R10: 安村 | S10: 山本高 | T10: 横田 | U10: 北川 | V10: 佐野 | W10: 田中 | X10: 岡本 | Y10: 市田 | Z10: 富島 | AA10: 丸田 | AB10: 中嶌 | AC10: 西村 | AD10: 欠員② | AE10: 井川 | AF10: 植山 | AG10: 門谷 | AH10: 上野 | AI10: 原 | AJ10: 谷川 | AK10: 上田 | AL10: 山田真 | AM10: 中山 | AN10: 尾川 | AO10: 山本幸 | AP10: 河野
A11: 2026-05-14 | B11: 木 | C11: 平日 | E11: 山本高 | F11: 栗下 | G11: 佐野 | H11: 中村 | I11: 尾川 | J11: 田中 | K11: 植山 | L11: 岩田 | M11: 西村 | N11: 安村 | O11: 岡本 | P11: 上田 | Q11: 藤原 | R11: 丸田 | S11: 山田真 | T11: 北川 | U11: 河野 | V11: 上野 | W11: 井川 | X11: 横山 | Y11: 谷川 | Z11: 中嶌 | AA11: 中山 | AB11: 大川内 | AC11: 山本幸 | AD11: 矢田 | AE11: 内野 | AF11: 野口 | AG11: 山田久 | AH11: 柴田 | AI11: 横田 | AJ11: 馬場 | AK11: 原 | AL11: 市田 | AM11: 欠員② | AN11: 門谷 | AO11: 欠員① | AP11: 富島
A12: 2026-05-15 | B12: 金 | C12: 平日 | E12: 山田真 | F12: 西村 | G12: 上野 | H12: 岡本 | I12: 門谷 | J12: 井川 | K12: 野口 | L12: 上田 | M12: 山本幸 | N12: 丸田 | O12: 横山 | P12: 原 | Q12: 岩田 | R12: 中山 | S12: 市田 | T12: 河野 | U12: 富島 | V12: 柴田 | W12: 内野 | X12: 植山 | Y12: 馬場 | Z12: 大川内 | AA12: 欠員② | AB12: 田中 | AC12: 欠員① | AD12: 佐野 | AE12: 中村 | AF12: 栗下 | AG12: 安村 | AH12: 藤原 | AI12: 北川 | AJ12: 尾川 | AK12: 横田 | AL12: 谷川 | AM12: 矢田 | AN12: 山田久 | AO12: 山本高 | AP12: 中嶌
A13: 2026-05-16 | B13: 土 | C13: 休日 | E13: 市田 | F13: 山本幸 | G13: 柴田 | H13: 横山 | I13: 山田久 | J13: 内野 | K13: 栗下 | L13: 原 | M13: 欠員① | N13: 中山 | O13: 植山 | P13: 横田 | Q13: 上田 | R13: 欠員② | S13: 谷川 | T13: 富島 | U13: 中嶌 | V13: 藤原 | W13: 中村 | X13: 野口 | Y13: 尾川 | Z13: 田中 | AA13: 矢田 | AB13: 井川 | AC13: 山本高 | AD13: 上野 | AE13: 岡本 | AF13: 西村 | AG13: 丸田 | AH13: 岩田 | AI13: 河野 | AJ13: 門谷 | AK13: 北川 | AL13: 馬場 | AM13: 佐野 | AN13: 安村 | AO13: 山田真 | AP13: 大川内
A14: 2026-05-17 | B14: 日 | C14: 休日 | E14: 谷川 | F14: 欠員① | G14: 藤原 | H14: 植山 | I14: 安村 | J14: 中村 | K14: 西村 | L14: 横田 | M14: 山本高 | N14: 欠員② | O14: 野口 | P14: 北川 | Q14: 原 | R14: 矢田 | S14: 馬場 | T14: 中嶌 | U14: 大川内 | V14: 岩田 | W14: 岡本 | X14: 栗下 | Y14: 門谷 | Z14: 井川 | AA14: 佐野 | AB14: 内野 | AC14: 山田真 | AD14: 柴田 | AE14: 横山 | AF14: 山本幸 | AG14: 中山 | AH14: 上田 | AI14: 富島 | AJ14: 山田久 | AK14: 河野 | AL14: 尾川 | AM14: 上野 | AN14: 丸田 | AO14: 市田 | AP14: 田中
A15: 2026-05-18 | B15: 月 | C15: 平日 | E15: 馬場 | F15: 山本高 | G15: 岩田 | H15: 野口 | I15: 丸田 | J15: 岡本 | K15: 山本幸 | L15: 北川 | M15: 山田真 | N15: 矢田 | O15: 栗下 | P15: 河野 | Q15: 横田 | R15: 佐野 | S15: 尾川 | T15: 大川内 | U15: 田中 | V15: 上田 | W15: 横山 | X15: 西村 | Y15: 山田久 | Z15: 内野 | AA15: 上野 | AB15: 中村 | AC15: 市田 | AD15: 藤原 | AE15: 植山 | AF15: 欠員① | AG15: 欠員② | AH15: 原 | AI15: 中嶌 | AJ15: 安村 | AK15: 富島 | AL15: 門谷 | AM15: 柴田 | AN15: 中山 | AO15: 谷川 | AP15: 井川
... A77: 2026-07-19 | B77: 日 | C77: 休日 | E77: 内野 | F77: 中嶌 | G77: 谷川 | H77: 原 | I77: 野口 | J77: 藤原 | K77: 河野 | L77: 山田久 | M77: 大川内 | N77: 山本幸 | O77: 横田 | P77: 安村 | Q77: 門谷 | R77: 欠員① | S77: 中村 | T77: 欠員② | U77: 矢田 | V77: 馬場 | W77: 岩田 | X77: 北川 | Y77: 横山 | Z77: 上野 | AA77: 山本高 | AB77: 柴田 | AC77: 田中 | AD77: 市田 | AE77: 上田 | AF77: 富島 | AG77: 西村 | AH77: 尾川 | AI77: 中山 | AJ77: 植山 | AK77: 丸田 | AL77: 岡本 | AM77: 山田真 | AN77: 栗下 | AO77: 井川 | AP77: 佐野
A78: 2026-07-20 | B78: 月 | C78: 休日 | D78: 海の日 | E78: 中村 | F78: 大川内 | G78: 馬場 | H78: 横田 | I78: 栗下 | J78: 岩田 | K78: 富島 | L78: 安村 | M78: 田中 | N78: 欠員① | O78: 北川 | P78: 丸田 | Q78: 山田久 | R78: 山本高 | S78: 岡本 | T78: 矢田 | U78: 佐野 | V78: 尾川 | W78: 上田 | X78: 河野 | Y78: 植山 | Z78: 柴田 | AA78: 山田真 | AB78: 藤原 | AC78: 井川 | AD78: 谷川 | AE78: 原 | AF78: 中嶌 | AG78: 山本幸 | AH78: 門谷 | AI78: 欠員② | AJ78: 野口 | AK78: 中山 | AL78: 横山 | AM78: 市田 | AN78: 西村 | AO78: 内野 | AP78: 上野
A79: 2026-07-21 | B79: 火 | C79: 平日 | E79: 岡本 | F79: 田中 | G79: 尾川 | H79: 北川 | I79: 西村 | J79: 上田 | K79: 中嶌 | L79: 丸田 | M79: 井川 | N79: 山本高 | O79: 河野 | P79: 中山 | Q79: 安村 | R79: 山田真 | S79: 横山 | T79: 佐野 | U79: 上野 | V79: 門谷 | W79: 原 | X79: 富島 | Y79: 野口 | Z79: 藤原 | AA79: 市田 | AB79: 岩田 | AC79: 内野 | AD79: 馬場 | AE79: 横田 | AF79: 大川内 | AG79: 欠員① | AH79: 山田久 | AI79: 矢田 | AJ79: 栗下 | AK79: 欠員② | AL79: 植山 | AM79: 谷川 | AN79: 山本幸 | AO79: 中村 | AP79: 柴田
A80: 2026-07-22 | B80: 水 | C80: 平日 | E80: 横山 | F80: 井川 | G80: 門谷 | H80: 河野 | I80: 山本幸 | J80: 原 | K80: 大川内 | L80: 中山 | M80: 内野 | N80: 山田真 | O80: 富島 | P80: 欠員② | Q80: 丸田 | R80: 市田 | S80: 植山 | T80: 上野 | U80: 柴田 | V80: 山田久 | W80: 横田 | X80: 中嶌 | Y80: 栗下 | Z80: 岩田 | AA80: 谷川 | AB80: 上田 | AC80: 中村 | AD80: 尾川 | AE80: 北川 | AF80: 田中 | AG80: 山本高 | AH80: 安村 | AI80: 佐野 | AJ80: 西村 | AK80: 矢田 | AL80: 野口 | AM80: 馬場 | AN80: 欠員① | AO80: 岡本 | AP80: 藤原
A81: 2026-07-23 | B81: 木 | C81: 平日 | E81: 植山 | F81: 内野 | G81: 山田久 | H81: 富島 | I81: 欠員① | J81: 横田 | K81: 田中 | L81: 欠員② | M81: 中村 | N81: 市田 | O81: 中嶌 | P81: 矢田 | Q81: 中山 | R81: 谷川 | S81: 野口 | T81: 柴田 | U81: 藤原 | V81: 安村 | W81: 北川 | X81: 大川内 | Y81: 西村 | Z81: 上田 | AA81: 馬場 | AB81: 原 | AC81: 岡本 | AD81: 門谷 | AE81: 河野 | AF81: 井川 | AG81: 山田真 | AH81: 丸田 | AI81: 上野 | AJ81: 山本幸 | AK81: 佐野 | AL81: 栗下 | AM81: 尾川 | AN81: 山本高 | AO81: 横山 | AP81: 岩田
A82: 2026-07-24 | B82: 金 | C82: 平日 | E82: 野口 | F82: 中村 | G82: 安村 | H82: 中嶌 | I82: 山本高 | J82: 北川 | K82: 井川 | L82: 矢田 | M82: 岡本 | N82: 谷川 | O82: 大川内 | P82: 佐野 | Q82: 欠員② | R82: 馬場 | S82: 栗下 | T82: 藤原 | U82: 岩田 | V82: 丸田 | W82: 河野 | X82: 田中 | Y82: 山本幸 | Z82: 原 | AA82: 尾川 | AB82: 横田 | AC82: 横山 | AD82: 山田久 | AE82: 富島 | AF82: 内野 | AG82: 市田 | AH82: 中山 | AI82: 柴田 | AJ82: 欠員① | AK82: 上野 | AL82: 西村 | AM82: 門谷 | AN82: 山田真 | AO82: 植山 | AP82: 上田
A83: 2026-07-25 | B83: 土 | C83: 休日 | E83: 栗下 | F83: 岡本 | G83: 丸田 | H83: 大川内 | I83: 山田真 | J83: 河野 | K83: 内野 | L83: 佐野 | M83: 横山 | N83: 馬場 | O83: 田中 | P83: 上野 | Q83: 矢田 | R83: 尾川 | S83: 西村 | T83: 岩田 | U83: 上田 | V83: 中山 | W83: 富島 | X83: 井川 | Y83: 欠員① | Z83: 横田 | AA83: 門谷 | AB83: 北川 | AC83: 植山 | AD83: 安村 | AE83: 中嶌 | AF83: 中村 | AG83: 谷川 | AH83: 欠員② | AI83: 藤原 | AJ83: 山本高 | AK83: 柴田 | AL83: 山本幸 | AM83: 山田久 | AN83: 市田 | AO83: 野口 | AP83: 原
A84: 2026-07-26 | B84: 日 | C84: 休日 | E84: 西村 | F84: 横山 | G84: 中山 | H84: 田中 | I84: 市田 | J84: 富島 | K84: 中村 | L84: 上野 | M84: 植山 | N84: 尾川 | O84: 井川 | P84: 柴田 | Q84: 佐野 | R84: 門谷 | S84: 山本幸 | T84: 上田 | U84: 原 | V84: 欠員② | W84: 中嶌 | X84: 内野 | Y84: 山本高 | Z84: 北川 | AA84: 山田久 | AB84: 河野 | AC84: 野口 | AD84: 丸田 | AE84: 大川内 | AF84: 岡本 | AG84: 馬場 | AH84: 矢田 | AI84: 岩田 | AJ84: 山田真 | AK84: 藤原 | AL84: 欠員① | AM84: 安村 | AN84: 谷川 | AO84: 栗下 | AP84: 横田
A85: 2026-07-27 | B85: 月 | C85: 平日 | E85: 山本幸 | F85: 植山 | G85: 欠員② | H85: 井川 | I85: 谷川 | J85: 中嶌 | K85: 岡本 | L85: 柴田 | M85: 野口 | N85: 門谷 | O85: 内野 | P85: 藤原 | Q85: 上野 | R85: 山田久 | S85: 欠員① | T85: 原 | U85: 横田 | V85: 矢田 | W85: 大川内 | X85: 中村 | Y85: 山田真 | Z85: 河野 | AA85: 安村 | AB85: 富島 | AC85: 栗下 | AD85: 中山 | AE85: 田中 | AF85: 横山 | AG85: 尾川 | AH85: 佐野 | AI85: 上田 | AJ85: 市田 | AK85: 岩田 | AL85: 山本高 | AM85: 丸田 | AN85: 馬場 | AO85: 西村 | AP85: 北川
A86: 2026-07-28 | B86: 火 | C86: 平日 | E86: 欠員① | F86: 野口 | G86: 矢田 | H86: 内野 | I86: 馬場 | J86: 大川内 | K86: 横山 | L86: 藤原 | M86: 栗下 | N86: 山田久 | O86: 中村 | P86: 岩田 | Q86: 柴田 | R86: 安村 | S86: 山本高 | T86: 横田 | U86: 北川 | V86: 佐野 | W86: 田中 | X86: 岡本 | Y86: 市田 | Z86: 富島 | AA86: 丸田 | AB86: 中嶌 | AC86: 西村 | AD86: 欠員② | AE86: 井川 | AF86: 植山 | AG86: 門谷 | AH86: 上野 | AI86: 原 | AJ86: 谷川 | AK86: 上田 | AL86: 山田真 | AM86: 中山 | AN86: 尾川 | AO86: 山本幸 | AP86: 河野
A87: 2026-07-29 | B87: 水 | C87: 平日 | E87: 山本高 | F87: 栗下 | G87: 佐野 | H87: 中村 | I87: 尾川 | J87: 田中 | K87: 植山 | L87: 岩田 | M87: 西村 | N87: 安村 | O87: 岡本 | P87: 上田 | Q87: 藤原 | R87: 丸田 | S87: 山田真 | T87: 北川 | U87: 河野 | V87: 上野 | W87: 井川 | X87: 横山 | Y87: 谷川 | Z87: 中嶌 | AA87: 中山 | AB87: 大川内 | AC87: 山本幸 | AD87: 矢田 | AE87: 内野 | AF87: 野口 | AG87: 山田久 | AH87: 柴田 | AI87: 横田 | AJ87: 馬場 | AK87: 原 | AL87: 市田 | AM87: 欠員② | AN87: 門谷 | AO87: 欠員① | AP87: 富島
A88: 2026-07-30 | B88: 木 | C88: 平日 | E88: 山田真 | F88: 西村 | G88: 上野 | H88: 岡本 | I88: 門谷 | J88: 井川 | K88: 野口 | L88: 上田 | M88: 山本幸 | N88: 丸田 | O88: 横山 | P88: 原 | Q88: 岩田 | R88: 中山 | S88: 市田 | T88: 河野 | U88: 富島 | V88: 柴田 | W88: 内野 | X88: 植山 | Y88: 馬場 | Z88: 大川内 | AA88: 欠員② | AB88: 田中 | AC88: 欠員① | AD88: 佐野 | AE88: 中村 | AF88: 栗下 | AG88: 安村 | AH88: 藤原 | AI88: 北川 | AJ88: 尾川 | AK88: 横田 | AL88: 谷川 | AM88: 矢田 | AN88: 山田久 | AO88: 山本高 | AP88: 中嶌
A89: 2026-07-31 | B89: 金 | C89: 平日 | E89: 市田 | F89: 山本幸 | G89: 柴田 | H89: 横山 | I89: 山田久 | J89: 内野 | K89: 栗下 | L89: 原 | M89: 欠員① | N89: 中山 | O89: 植山 | P89: 横田 | Q89: 上田 | R89: 欠員② | S89: 谷川 | T89: 富島 | U89: 中嶌 | V89: 藤原 | W89: 中村 | X89: 野口 | Y89: 尾川 | Z89: 田中 | AA89: 矢田 | AB89: 井川 | AC89: 山本高 | AD89: 上野 | AE89: 岡本 | AF89: 西村 | AG89: 丸田 | AH89: 岩田 | AI89: 河野 | AJ89: 門谷 | AK89: 北川 | AL89: 馬場 | AM89: 佐野 | AN89: 安村 | AO89: 山田真 | AP89: 大川内
A90: 2026-08-01 | B90: 土 | C90: 休日 | E90: 谷川 | F90: 欠員① | G90: 藤原 | H90: 植山 | I90: 安村 | J90: 中村 | K90: 西村 | L90: 横田 | M90: 山本高 | N90: 欠員② | O90: 野口 | P90: 北川 | Q90: 原 | R90: 矢田 | S90: 馬場 | T90: 中嶌 | U90: 大川内 | V90: 岩田 | W90: 岡本 | X90: 栗下 | Y90: 門谷 | Z90: 井川 | AA90: 佐野 | AB90: 内野 | AC90: 山田真 | AD90: 柴田 | AE90: 横山 | AF90: 山本幸 | AG90: 中山 | AH90: 上田 | AI90: 富島 | AJ90: 山田久 | AK90: 河野 | AL90: 尾川 | AM90: 上野 | AN90: 丸田 | AO90: 市田 | AP90: 田中
... A99: 2026-08-10 | B99: 月 | C99: 平日 | E99: 矢田 | F99: 安村 | G99: 大川内 | H99: 谷川 | I99: 岩田 | J99: 山本高 | K99: 門谷 | L99: 中村 | M99: 丸田 | N99: 横田 | O99: 馬場 | P99: 岡本 | Q99: 内野 | R99: 北川 | S99: 佐野 | T99: 野口 | U99: 栗下 | V99: 田中 | W99: 山田真 | X99: 尾川 | Y99: 柴田 | Z99: 山本幸 | AA99: 河野 | AB99: 欠員① | AC99: 中山 | AD99: 中嶌 | AE99: 市田 | AF99: 山田久 | AG99: 原 | AH99: 井川 | AI99: 植山 | AJ99: 藤原 | AK99: 横山 | AL99: 上野 | AM99: 富島 | AN99: 上田 | AO99: 欠員② | AP99: 西村
A100: 2026-08-11 | B100: 火 | C100: 休日 | D100: 山の日 | E100: 佐野 | F100: 丸田 | G100: 田中 | H100: 馬場 | I100: 上田 | J100: 山田真 | K100: 山田久 | L100: 岡本 | M100: 中山 | N100: 北川 | O100: 尾川 | P100: 横山 | Q100: 中村 | R100: 河野 | S100: 上野 | T100: 栗下 | U100: 西村 | V100: 井川 | W100: 市田 | X100: 門谷 | Y100: 藤原 | Z100: 欠員① | AA100: 富島 | AB100: 山本高 | AC100: 欠員② | AD100: 大川内 | AE100: 谷川 | AF100: 安村 | AG100: 横田 | AH100: 内野 | AI100: 野口 | AJ100: 岩田 | AK100: 植山 | AL100: 柴田 | AM100: 中嶌 | AN100: 原 | AO100: 矢田 | AP100: 山本幸
A101: 2026-08-12 | B101: 水 | C101: 平日 | E101: 上野 | F101: 中山 | G101: 井川 | H101: 尾川 | I101: 原 | J101: 市田 | K101: 安村 | L101: 横山 | M101: 欠員② | N101: 河野 | O101: 門谷 | P101: 植山 | Q101: 岡本 | R101: 富島 | S101: 柴田 | T101: 西村 | U101: 山本幸 | V101: 内野 | W101: 谷川 | X101: 山田久 | Y101: 岩田 | Z101: 山本高 | AA101: 中嶌 | AB101: 山田真 | AC101: 矢田 | AD101: 田中 | AE101: 馬場 | AF101: 丸田 | AG101: 北川 | AH101: 中村 | AI101: 栗下 | AJ101: 上田 | AK101: 野口 | AL101: 藤原 | AM101: 大川内 | AN101: 横田 | AO101: 佐野 | AP101: 欠員①
A102: 2026-08-13 | B102: 木 | C102: 平日 | E102: 柴田 | F102: 欠員② | G102: 内野 | H102: 門谷 | I102: 横田 | J102: 谷川 | K102: 丸田 | L102: 植山 | M102: 矢田 | N102: 富島 | O102: 山田久 | P102: 野口 | Q102: 横山 | R102: 中嶌 | S102: 藤原 | T102: 山本幸 | U102: 欠員① | V102: 中村 | W102: 馬場 | X102: 安村 | Y102: 上田 | Z102: 山田真 | AA102: 大川内 | AB102: 市田 | AC102: 佐野 | AD102: 井川 | AE102: 尾川 | AF102: 中山 | AG102: 河野 | AH102: 岡本 | AI102: 西村 | AJ102: 原 | AK102: 栗下 | AL102: 岩田 | AM102: 田中 | AN102: 北川 | AO102: 上野 | AP102: 山本高
A103: 2026-08-14 | B103: 金 | C103: 平日 | E103: 藤原 | F103: 矢田 | G103: 中村 | H103: 山田久 | I103: 北川 | J103: 馬場 | K103: 中山 | L103: 野口 | M103: 佐野 | N103: 中嶌 | O103: 安村 | P103: 栗下 | Q103: 植山 | R103: 大川内 | S103: 岩田 | T103: 欠員① | U103: 山本高 | V103: 岡本 | W103: 尾川 | X103: 丸田 | Y103: 原 | Z103: 市田 | AA103: 田中 | AB103: 谷川 | AC103: 上野 | AD103: 内野 | AE103: 門谷 | AF103: 欠員② | AG103: 富島 | AH103: 横山 | AI103: 山本幸 | AJ103: 横田 | AK103: 西村 | AL103: 上田 | AM103: 井川 | AN103: 河野 | AO103: 柴田 | AP103: 山田真
A104: 2026-08-15 | B104: 土 | C104: 休日 | E104: 岩田 | F104: 佐野 | G104: 岡本 | H104: 安村 | I104: 河野 | J104: 尾川 | K104: 欠員② | L104: 栗下 | M104: 上野 | N104: 大川内 | O104: 丸田 | P104: 西村 | Q104: 野口 | R104: 田中 | S104: 上田 | T104: 山本高 | U104: 山田真 | V104: 横山 | W104: 門谷 | X104: 中山 | Y104: 横田 | Z104: 谷川 | AA104: 井川 | AB104: 馬場 | AC104: 柴田 | AD104: 中村 | AE104: 山田久 | AF104: 矢田 | AG104: 中嶌 | AH104: 植山 | AI104: 欠員① | AJ104: 北川 | AK104: 山本幸 | AL104: 原 | AM104: 内野 | AN104: 富島 | AO104: 藤原 | AP104: 市田
A105: 2026-08-16 | B105: 日 | C105: 休日 | E105: 上田 | F105: 上野 | G105: 横山 | H105: 丸田 | I105: 富島 | J105: 門谷 | K105: 矢田 | L105: 西村 | M105: 柴田 | N105: 田中 | O105: 中山 | P105: 山本幸 | Q105: 栗下 | R105: 井川 | S105: 原 | T105: 山田真 | U105: 市田 | V105: 植山 | W105: 山田久 | X105: 欠員② | Y105: 北川 | Z105: 馬場 | AA105: 内野 | AB105: 尾川 | AC105: 藤原 | AD105: 岡本 | AE105: 安村 | AF105: 佐野 | AG105: 大川内 | AH105: 野口 | AI105: 山本高 | AJ105: 河野 | AK105: 欠員① | AL105: 横田 | AM105: 中村 | AN105: 中嶌 | AO105: 岩田 | AP105: 谷川
A106: 2026-08-17 | B106: 月 | C106: 平日 | E106: 原 | F106: 柴田 | G106: 植山 | H106: 中山 | I106: 中嶌 | J106: 山田久 | K106: 佐野 | L106: 山本幸 | M106: 藤原 | N106: 井川 | O106: 欠員② | P106: 欠員① | Q106: 西村 | R106: 内野 | S106: 横田 | T106: 市田 | U106: 谷川 | V106: 野口 | W106: 安村 | X106: 矢田 | Y106: 河野 | Z106: 尾川 | AA106: 中村 | AB106: 門谷 | AC106: 岩田 | AD106: 横山 | AE106: 丸田 | AF106: 上野 | AG106: 田中 | AH106: 栗下 | AI106: 山田真 | AJ106: 富島 | AK106: 山本高 | AL106: 北川 | AM106: 岡本 | AN106: 大川内 | AO106: 上田 | AP106: 馬場
A107: 2026-08-18 | B107: 火 | C107: 平日 | E107: 横田 | F107: 藤原 | G107: 野口 | H107: 欠員② | I107: 大川内 | J107: 安村 | K107: 上野 | L107: 欠員① | M107: 岩田 | N107: 内野 | O107: 矢田 | P107: 山本高 | Q107: 山本幸 | R107: 中村 | S107: 北川 | T107: 谷川 | U107: 馬場 | V107: 栗下 | W107: 丸田 | X107: 佐野 | Y107: 富島 | Z107: 門谷 | AA107: 岡本 | AB107: 山田久 | AC107: 上田 | AD107: 植山 | AE107: 中山 | AF107: 柴田 | AG107: 井川 | AH107: 西村 | AI107: 市田 | AJ107: 中嶌 | AK107: 山田真 | AL107: 河野 | AM107: 横山 | AN107: 田中 | AO107: 原 | AP107: 尾川
A108: 2026-08-19 | B108: 水 | C108: 平日 | E108: 北川 | F108: 岩田 | G108: 栗下 | H108: 矢田 | I108: 田中 | J108: 丸田 | K108: 柴田 | L108: 山本高 | M108: 上田 | N108: 中村 | O108: 佐野 | P108: 山田真 | Q108: 欠員① | R108: 岡本 | S108: 河野 | T108: 馬場 | U108: 尾川 | V108: 西村 | W108: 中山 | X108: 上野 | Y108: 中嶌 | Z108: 山田久 | AA108: 横山 | AB108: 安村 | AC108: 原 | AD108: 野口 | AE108: 欠員② | AF108: 藤原 | AG108: 内野 | AH108: 山本幸 | AI108: 谷川 | AJ108: 大川内 | AK108: 市田 | AL108: 富島 | AM108: 植山 | AN108: 井川 | AO108: 横田 | AP108: 門谷
A109: 2026-08-20 | B109: 木 | C109: 平日 | E109: 河野 | F109: 上田 | G109: 西村 | H109: 佐野 | I109: 井川 | J109: 中山 | K109: 藤原 | L109: 山田真 | M109: 原 | N109: 岡本 | O109: 上野 | P109: 市田 | Q109: 山本高 | R109: 横山 | S109: 富島 | T109: 尾川 | U109: 門谷 | V109: 山本幸 | W109: 欠員② | X109: 柴田 | Y109: 大川内 | Z109: 安村 | AA109: 植山 | AB109: 丸田 | AC109: 横田 | AD109: 栗下 | AE109: 矢田 | AF109: 岩田 | AG109: 中村 | AH109: 欠員① | AI109: 馬場 | AJ109: 田中 | AK109: 谷川 | AL109: 中嶌 | AM109: 野口 | AN109: 内野 | AO109: 北川 | AP109: 山田久
...

Sheet 出退勤マスタ
A1: 系統 | B1: 区分 | C1: 勤務 | D1: 出勤 | E1: 退勤 | F1: 備考
A2: 1 | B2: 平日 | C2: 通常 | D2: 05:25 | E2: 14:15
A3: 1 | B3: 休日 | C3: 通常 | D3: 05:10 | E3: 13:55
A4: 2 | B4: 平日 | C4: 通常 | D4: 05:40 | E4: 14:35
A5: 2 | B5: 休日 | C5: 通常 | D5: 05:25 | E5: 14:15
A6: 3 | B6: 平日 | C6: 通常 | D6: 05:40 | E6: 14:45
A7: 3 | B7: 休日 | C7: 通常 | D7: 05:40 | E7: 14:25
A8: 4 | B8: 平日 | C8: 通常 | D8: 06:00 | E8: 15:05
A9: 4 | B9: 休日 | C9: 通常 | D9: 05:40 | E9: 14:45
A10: 5 | B10: 平日 | C10: 通常 | D10: 06:15 | E10: 15:25
A11: 5 | B11: 休日 | C11: 通常 | D11: 06:15 | E11: 15:05
A12: 6 | B12: 平日 | C12: 通常 | D12: 06:35 | E12: 15:55
A13: 6 | B13: 休日 | C13: 通常 | D13: 06:35 | E13: 15:35
... A15: 7 | B15: 休日 | C15: 通常 | D15: 08:45 | E15: 17:25
A16: 8 | B16: 平日 | C16: 1回目 | D16: 05:10 | E16: 08:50 | F16: 中休勤務(2回出勤)
A17: 8 | B17: 平日 | C17: 2回目 | D17: 17:25 | E17: 21:55 | F17: 中休勤務(2回出勤)
A18: 8 | B18: 休日 | C18: 1回目 | D18: 08:15 | E18: 12:35 | F18: 中休勤務(2回出勤)
A19: 8 | B19: 休日 | C19: 2回目 | D19: 17:25 | E19: 20:30 | F19: 中休勤務(2回出勤)
A20: 9 | B20: 平日 | C20: 1回目 | D20: 09:05 | E20: 13:25 | F20: 中休勤務(2回出勤)
A21: 9 | B21: 平日 | C21: 2回目 | D21: 17:45 | E21: 21:05 | F21: 中休勤務(2回出勤)
A22: 9 | B22: 休日 | C22: 通常 | D22: 13:35 | E22: 22:15
A23: 10 | B23: 平日 | C23: 通常 | D23: 13:55 | E23: 22:40
A24: 10 | B24: 休日 | C24: 通常 | D24: 13:55 | E24: 22:25
A25: 11 | B25: 平日 | C25: 通常 | D25: 14:25 | E25: 23:00
A26: 11 | B26: 休日 | C26: 通常 | D26: 14:25 | E26: 23:00
A27: 12 | B27: 平日 | C27: 通常 | D27: 14:45 | E27: 23:55
A28: 12 | B28: 休日 | C28: 通常 | D28: 14:45 | E28: 23:55
A29: 13 | B29: 平日 | C29: 通常 | D29: 15:05 | E29: 00:05 | F29: 退勤翌日
A30: 13 | B30: 休日 | C30: 通常 | D30: 15:15 | E30: 00:05 | F30: 退勤翌日
A31: 14 | B31: 平日 | C31: 通常 | D31: 15:35 | E31: 00:20 | F31: 退勤翌日
A32: 14 | B32: 休日 | C32: 通常 | D32: 15:35 | E32: 00:20 | F32: 退勤翌日
A33: 15 | B33: 平日 | C33: 通常 | D33: 15:55 | E33: 00:40 | F33: 退勤翌日
A34: 15 | B34: 休日 | C34: 通常 | D34: 17:05 | E34: 00:40 | F34: 退勤翌日
A35: 16 | B35: 平日 | C35: 通常 | D35: 05:10 | E35: 14:15
A36: 16 | B36: 休日 | C36: 通常 | D36: 05:10 | E36: 14:05
A37: 17 | B37: 平日 | C37: 通常 | D37: 05:20 | E37: 14:35
A38: 17 | B38: 休日 | C38: 通常 | D38: 05:20 | E38: 14:15
A39: 18 | B39: 平日 | C39: 通常 | D39: 06:20 | E39: 15:45
A40: 18 | B40: 休日 | C40: 通常 | D40: 06:30 | E40: 15:05
A41: 19 | B41: 平日 | C41: 通常 | D41: 06:30 | E41: 16:05
...

Sheet 当日休憩ビュー
A1: 当日休憩ビュー
A2: 当日早見表の日付に連動し当日ダイヤの休憩を自動抽出。
A3: 対象日 | B3: =当日早見表!B1 | C3: ダイヤ | D3: =当日早見表!B3 | E3: 件数 | F3: =COUNTIF(休憩マスタ!$A$5:$A$61,当日早見表!$B$3)
A5: 開始 | B5: 終了 | C5: 所要分 | D5: 系統 | E5: 担当運転士 | F5: 交代駅 | G5: 区分
A6: =IF($J6="","",INDEX(休憩マスタ!$C$5:$C$61,$J6)) | B6: =IF($J6="","",INDEX(休憩マスタ!$D$5:$D$61,$J6)) | C6: =IF($J6="","",INDEX(休憩マスタ!$E$5:$E$61,$J6)) | D6: =IF($J6="","",INDEX(休憩マスタ!$B$5:$B$61,$J6)) | E6: =IF($J6="","",INDEX(休憩マスタ!$J$5:$J$61,$J6)) | F6: =IF($J6="","",INDEX(休憩マスタ!$F$5:$F$61,$J6)) | G6: =IF($J6="","",INDEX(休憩マスタ!$H$5:$H$61,$J6)) | J6: =IFERROR(MATCH(1,休憩マスタ!$I$5:$I$61,0),"")
A7: =IF($J7="","",INDEX(休憩マスタ!$C$5:$C$61,$J7)) | B7: =IF($J7="","",INDEX(休憩マスタ!$D$5:$D$61,$J7)) | C7: =IF($J7="","",INDEX(休憩マスタ!$E$5:$E$61,$J7)) | D7: =IF($J7="","",INDEX(休憩マスタ!$B$5:$B$61,$J7)) | E7: =IF($J7="","",INDEX(休憩マスタ!$J$5:$J$61,$J7)) | F7: =IF($J7="","",INDEX(休憩マスタ!$F$5:$F$61,$J7)) | G7: =IF($J7="","",INDEX(休憩マスタ!$H$5:$H$61,$J7)) | J7: =IFERROR(MATCH(2,休憩マスタ!$I$5:$I$61,0),"")
A8: =IF($J8="","",INDEX(休憩マスタ!$C$5:$C$61,$J8)) | B8: =IF($J8="","",INDEX(休憩マスタ!$D$5:$D$61,$J8)) | C8: =IF($J8="","",INDEX(休憩マスタ!$E$5:$E$61,$J8)) | D8: =IF($J8="","",INDEX(休憩マスタ!$B$5:$B$61,$J8)) | E8: =IF($J8="","",INDEX(休憩マスタ!$J$5:$J$61,$J8)) | F8: =IF($J8="","",INDEX(休憩マスタ!$F$5:$F$61,$J8)) | G8: =IF($J8="","",INDEX(休憩マスタ!$H$5:$H$61,$J8)) | J8: =IFERROR(MATCH(3,休憩マスタ!$I$5:$I$61,0),"")
A9: =IF($J9="","",INDEX(休憩マスタ!$C$5:$C$61,$J9)) | B9: =IF($J9="","",INDEX(休憩マスタ!$D$5:$D$61,$J9)) | C9: =IF($J9="","",INDEX(休憩マスタ!$E$5:$E$61,$J9)) | D9: =IF($J9="","",INDEX(休憩マスタ!$B$5:$B$61,$J9)) | E9: =IF($J9="","",INDEX(休憩マスタ!$J$5:$J$61,$J9)) | F9: =IF($J9="","",INDEX(休憩マスタ!$F$5:$F$61,$J9)) | G9: =IF($J9="","",INDEX(休憩マスタ!$H$5:$H$61,$J9)) | J9: =IFERROR(MATCH(4,休憩マスタ!$I$5:$I$61,0),"")
A10: =IF($J10="","",INDEX(休憩マスタ!$C$5:$C$61,$J10)) | B10: =IF($J10="","",INDEX(休憩マスタ!$D$5:$D$61,$J10)) | C10: =IF($J10="","",INDEX(休憩マスタ!$E$5:$E$61,$J10)) | D10: =IF($J10="","",INDEX(休憩マスタ!$B$5:$B$61,$J10)) | E10: =IF($J10="","",INDEX(休憩マスタ!$J$5:$J$61,$J10)) | F10: =IF($J10="","",INDEX(休憩マスタ!$F$5:$F$61,$J10)) | G10: =IF($J10="","",INDEX(休憩マスタ!$H$5:$H$61,$J10)) | J10: =IFERROR(MATCH(5,休憩マスタ!$I$5:$I$61,0),"")
A11: =IF($J11="","",INDEX(休憩マスタ!$C$5:$C$61,$J11)) | B11: =IF($J11="","",INDEX(休憩マスタ!$D$5:$D$61,$J11)) | C11: =IF($J11="","",INDEX(休憩マスタ!$E$5:$E$61,$J11)) | D11: =IF($J11="","",INDEX(休憩マスタ!$B$5:$B$61,$J11)) | E11: =IF($J11="","",INDEX(休憩マスタ!$J$5:$J$61,$J11)) | F11: =IF($J11="","",INDEX(休憩マスタ!$F$5:$F$61,$J11)) | G11: =IF($J11="","",INDEX(休憩マスタ!$H$5:$H$61,$J11)) | J11: =IFERROR(MATCH(6,休憩マスタ!$I$5:$I$61,0),"")
A12: =IF($J12="","",INDEX(休憩マスタ!$C$5:$C$61,$J12)) | B12: =IF($J12="","",INDEX(休憩マスタ!$D$5:$D$61,$J12)) | C12: =IF($J12="","",INDEX(休憩マスタ!$E$5:$E$61,$J12)) | D12: =IF($J12="","",INDEX(休憩マスタ!$B$5:$B$61,$J12)) | E12: =IF($J12="","",INDEX(休憩マスタ!$J$5:$J$61,$J12)) | F12: =IF($J12="","",INDEX(休憩マスタ!$F$5:$F$61,$J12)) | G12: =IF($J12="","",INDEX(休憩マスタ!$H$5:$H$61,$J12)) | J12: =IFERROR(MATCH(7,休憩マスタ!$I$5:$I$61,0),"")
A13: =IF($J13="","",INDEX(休憩マスタ!$C$5:$C$61,$J13)) | B13: =IF($J13="","",INDEX(休憩マスタ!$D$5:$D$61,$J13)) | C13: =IF($J13="","",INDEX(休憩マスタ!$E$5:$E$61,$J13)) | D13: =IF($J13="","",INDEX(休憩マスタ!$B$5:$B$61,$J13)) | E13: =IF($J13="","",INDEX(休憩マスタ!$J$5:$J$61,$J13)) | F13: =IF($J13="","",INDEX(休憩マスタ!$F$5:$F$61,$J13)) | G13: =IF($J13="","",INDEX(休憩マスタ!$H$5:$H$61,$J13)) | J13: =IFERROR(MATCH(8,休憩マスタ!$I$5:$I$61,0),"")
A14: =IF($J14="","",INDEX(休憩マスタ!$C$5:$C$61,$J14)) | B14: =IF($J14="","",INDEX(休憩マスタ!$D$5:$D$61,$J14)) | C14: =IF($J14="","",INDEX(休憩マスタ!$E$5:$E$61,$J14)) | D14: =IF($J14="","",INDEX(休憩マスタ!$B$5:$B$61,$J14)) | E14: =IF($J14="","",INDEX(休憩マスタ!$J$5:$J$61,$J14)) | F14: =IF($J14="","",INDEX(休憩マスタ!$F$5:$F$61,$J14)) | G14: =IF($J14="","",INDEX(休憩マスタ!$H$5:$H$61,$J14)) | J14: =IFERROR(MATCH(9,休憩マスタ!$I$5:$I$61,0),"")
A15: =IF($J15="","",INDEX(休憩マスタ!$C$5:$C$61,$J15)) | B15: =IF($J15="","",INDEX(休憩マスタ!$D$5:$D$61,$J15)) | C15: =IF($J15="","",INDEX(休憩マスタ!$E$5:$E$61,$J15)) | D15: =IF($J15="","",INDEX(休憩マスタ!$B$5:$B$61,$J15)) | E15: =IF($J15="","",INDEX(休憩マスタ!$J$5:$J$61,$J15)) | F15: =IF($J15="","",INDEX(休憩マスタ!$F$5:$F$61,$J15)) | G15: =IF($J15="","",INDEX(休憩マスタ!$H$5:$H$61,$J15)) | J15: =IFERROR(MATCH(10,休憩マスタ!$I$5:$I$61,0),"")
A16: =IF($J16="","",INDEX(休憩マスタ!$C$5:$C$61,$J16)) | B16: =IF($J16="","",INDEX(休憩マスタ!$D$5:$D$61,$J16)) | C16: =IF($J16="","",INDEX(休憩マスタ!$E$5:$E$61,$J16)) | D16: =IF($J16="","",INDEX(休憩マスタ!$B$5:$B$61,$J16)) | E16: =IF($J16="","",INDEX(休憩マスタ!$J$5:$J$61,$J16)) | F16: =IF($J16="","",INDEX(休憩マスタ!$F$5:$F$61,$J16)) | G16: =IF($J16="","",INDEX(休憩マスタ!$H$5:$H$61,$J16)) | J16: =IFERROR(MATCH(11,休憩マスタ!$I$5:$I$61,0),"")
A17: =IF($J17="","",INDEX(休憩マスタ!$C$5:$C$61,$J17)) | B17: =IF($J17="","",INDEX(休憩マスタ!$D$5:$D$61,$J17)) | C17: =IF($J17="","",INDEX(休憩マスタ!$E$5:$E$61,$J17)) | D17: =IF($J17="","",INDEX(休憩マスタ!$B$5:$B$61,$J17)) | E17: =IF($J17="","",INDEX(休憩マスタ!$J$5:$J$61,$J17)) | F17: =IF($J17="","",INDEX(休憩マスタ!$F$5:$F$61,$J17)) | G17: =IF($J17="","",INDEX(休憩マスタ!$H$5:$H$61,$J17)) | J17: =IFERROR(MATCH(12,休憩マスタ!$I$5:$I$61,0),"")
A18: =IF($J18="","",INDEX(休憩マスタ!$C$5:$C$61,$J18)) | B18: =IF($J18="","",INDEX(休憩マスタ!$D$5:$D$61,$J18)) | C18: =IF($J18="","",INDEX(休憩マスタ!$E$5:$E$61,$J18)) | D18: =IF($J18="","",INDEX(休憩マスタ!$B$5:$B$61,$J18)) | E18: =IF($J18="","",INDEX(休憩マスタ!$J$5:$J$61,$J18)) | F18: =IF($J18="","",INDEX(休憩マスタ!$F$5:$F$61,$J18)) | G18: =IF($J18="","",INDEX(休憩マスタ!$H$5:$H$61,$J18)) | J18: =IFERROR(MATCH(13,休憩マスタ!$I$5:$I$61,0),"")
A19: =IF($J19="","",INDEX(休憩マスタ!$C$5:$C$61,$J19)) | B19: =IF($J19="","",INDEX(休憩マスタ!$D$5:$D$61,$J19)) | C19: =IF($J19="","",INDEX(休憩マスタ!$E$5:$E$61,$J19)) | D19: =IF($J19="","",INDEX(休憩マスタ!$B$5:$B$61,$J19)) | E19: =IF($J19="","",INDEX(休憩マスタ!$J$5:$J$61,$J19)) | F19: =IF($J19="","",INDEX(休憩マスタ!$F$5:$F$61,$J19)) | G19: =IF($J19="","",INDEX(休憩マスタ!$H$5:$H$61,$J19)) | J19: =IFERROR(MATCH(14,休憩マスタ!$I$5:$I$61,0),"")
A20: =IF($J20="","",INDEX(休憩マスタ!$C$5:$C$61,$J20)) | B20: =IF($J20="","",INDEX(休憩マスタ!$D$5:$D$61,$J20)) | C20: =IF($J20="","",INDEX(休憩マスタ!$E$5:$E$61,$J20)) | D20: =IF($J20="","",INDEX(休憩マスタ!$B$5:$B$61,$J20)) | E20: =IF($J20="","",INDEX(休憩マスタ!$J$5:$J$61,$J20)) | F20: =IF($J20="","",INDEX(休憩マスタ!$F$5:$F$61,$J20)) | G20: =IF($J20="","",INDEX(休憩マスタ!$H$5:$H$61,$J20)) | J20: =IFERROR(MATCH(15,休憩マスタ!$I$5:$I$61,0),"")
A21: =IF($J21="","",INDEX(休憩マスタ!$C$5:$C$61,$J21)) | B21: =IF($J21="","",INDEX(休憩マスタ!$D$5:$D$61,$J21)) | C21: =IF($J21="","",INDEX(休憩マスタ!$E$5:$E$61,$J21)) | D21: =IF($J21="","",INDEX(休憩マスタ!$B$5:$B$61,$J21)) | E21: =IF($J21="","",INDEX(休憩マスタ!$J$5:$J$61,$J21)) | F21: =IF($J21="","",INDEX(休憩マスタ!$F$5:$F$61,$J21)) | G21: =IF($J21="","",INDEX(休憩マスタ!$H$5:$H$61,$J21)) | J21: =IFERROR(MATCH(16,休憩マスタ!$I$5:$I$61,0),"")
A22: =IF($J22="","",INDEX(休憩マスタ!$C$5:$C$61,$J22)) | B22: =IF($J22="","",INDEX(休憩マスタ!$D$5:$D$61,$J22)) | C22: =IF($J22="","",INDEX(休憩マスタ!$E$5:$E$61,$J22)) | D22: =IF($J22="","",INDEX(休憩マスタ!$B$5:$B$61,$J22)) | E22: =IF($J22="","",INDEX(休憩マスタ!$J$5:$J$61,$J22)) | F22: =IF($J22="","",INDEX(休憩マスタ!$F$5:$F$61,$J22)) | G22: =IF($J22="","",INDEX(休憩マスタ!$H$5:$H$61,$J22)) | J22: =IFERROR(MATCH(17,休憩マスタ!$I$5:$I$61,0),"")
A23: =IF($J23="","",INDEX(休憩マスタ!$C$5:$C$61,$J23)) | B23: =IF($J23="","",INDEX(休憩マスタ!$D$5:$D$61,$J23)) | C23: =IF($J23="","",INDEX(休憩マスタ!$E$5:$E$61,$J23)) | D23: =IF($J23="","",INDEX(休憩マスタ!$B$5:$B$61,$J23)) | E23: =IF($J23="","",INDEX(休憩マスタ!$J$5:$J$61,$J23)) | F23: =IF($J23="","",INDEX(休憩マスタ!$F$5:$F$61,$J23)) | G23: =IF($J23="","",INDEX(休憩マスタ!$H$5:$H$61,$J23)) | J23: =IFERROR(MATCH(18,休憩マスタ!$I$5:$I$61,0),"")
A24: =IF($J24="","",INDEX(休憩マスタ!$C$5:$C$61,$J24)) | B24: =IF($J24="","",INDEX(休憩マスタ!$D$5:$D$61,$J24)) | C24: =IF($J24="","",INDEX(休憩マスタ!$E$5:$E$61,$J24)) | D24: =IF($J24="","",INDEX(休憩マスタ!$B$5:$B$61,$J24)) | E24: =IF($J24="","",INDEX(休憩マスタ!$J$5:$J$61,$J24)) | F24: =IF($J24="","",INDEX(休憩マスタ!$F$5:$F$61,$J24)) | G24: =IF($J24="","",INDEX(休憩マスタ!$H$5:$H$61,$J24)) | J24: =IFERROR(MATCH(19,休憩マスタ!$I$5:$I$61,0),"")
A25: =IF($J25="","",INDEX(休憩マスタ!$C$5:$C$61,$J25)) | B25: =IF($J25="","",INDEX(休憩マスタ!$D$5:$D$61,$J25)) | C25: =IF($J25="","",INDEX(休憩マスタ!$E$5:$E$61,$J25)) | D25: =IF($J25="","",INDEX(休憩マスタ!$B$5:$B$61,$J25)) | E25: =IF($J25="","",INDEX(休憩マスタ!$J$5:$J$61,$J25)) | F25: =IF($J25="","",INDEX(休憩マスタ!$F$5:$F$61,$J25)) | G25: =IF($J25="","",INDEX(休憩マスタ!$H$5:$H$61,$J25)) | J25: =IFERROR(MATCH(20,休憩マスタ!$I$5:$I$61,0),"")
A26: =IF($J26="","",INDEX(休憩マスタ!$C$5:$C$61,$J26)) | B26: =IF($J26="","",INDEX(休憩マスタ!$D$5:$D$61,$J26)) | C26: =IF($J26="","",INDEX(休憩マスタ!$E$5:$E$61,$J26)) | D26: =IF($J26="","",INDEX(休憩マスタ!$B$5:$B$61,$J26)) | E26: =IF($J26="","",INDEX(休憩マスタ!$J$5:$J$61,$J26)) | F26: =IF($J26="","",INDEX(休憩マスタ!$F$5:$F$61,$J26)) | G26: =IF($J26="","",INDEX(休憩マスタ!$H$5:$H$61,$J26)) | J26: =IFERROR(MATCH(21,休憩マスタ!$I$5:$I$61,0),"")
A27: =IF($J27="","",INDEX(休憩マスタ!$C$5:$C$61,$J27)) | B27: =IF($J27="","",INDEX(休憩マスタ!$D$5:$D$61,$J27)) | C27: =IF($J27="","",INDEX(休憩マスタ!$E$5:$E$61,$J27)) | D27: =IF($J27="","",INDEX(休憩マスタ!$B$5:$B$61,$J27)) | E27: =IF($J27="","",INDEX(休憩マスタ!$J$5:$J$61,$J27)) | F27: =IF($J27="","",INDEX(休憩マスタ!$F$5:$F$61,$J27)) | G27: =IF($J27="","",INDEX(休憩マスタ!$H$5:$H$61,$J27)) | J27: =IFERROR(MATCH(22,休憩マスタ!$I$5:$I$61,0),"")
A28: =IF($J28="","",INDEX(休憩マスタ!$C$5:$C$61,$J28)) | B28: =IF($J28="","",INDEX(休憩マスタ!$D$5:$D$61,$J28)) | C28: =IF($J28="","",INDEX(休憩マスタ!$E$5:$E$61,$J28)) | D28: =IF($J28="","",INDEX(休憩マスタ!$B$5:$B$61,$J28)) | E28: =IF($J28="","",INDEX(休憩マスタ!$J$5:$J$61,$J28)) | F28: =IF($J28="","",INDEX(休憩マスタ!$F$5:$F$61,$J28)) | G28: =IF($J28="","",INDEX(休憩マスタ!$H$5:$H$61,$J28)) | J28: =IFERROR(MATCH(23,休憩マスタ!$I$5:$I$61,0),"")
A29: =IF($J29="","",INDEX(休憩マスタ!$C$5:$C$61,$J29)) | B29: =IF($J29="","",INDEX(休憩マスタ!$D$5:$D$61,$J29)) | C29: =IF($J29="","",INDEX(休憩マスタ!$E$5:$E$61,$J29)) | D29: =IF($J29="","",INDEX(休憩マスタ!$B$5:$B$61,$J29)) | E29: =IF($J29="","",INDEX(休憩マスタ!$J$5:$J$61,$J29)) | F29: =IF($J29="","",INDEX(休憩マスタ!$F$5:$F$61,$J29)) | G29: =IF($J29="","",INDEX(休憩マスタ!$H$5:$H$61,$J29)) | J29: =IFERROR(MATCH(24,休憩マスタ!$I$5:$I$61,0),"")
A30: =IF($J30="","",INDEX(休憩マスタ!$C$5:$C$61,$J30)) | B30: =IF($J30="","",INDEX(休憩マスタ!$D$5:$D$61,$J30)) | C30: =IF($J30="","",INDEX(休憩マスタ!$E$5:$E$61,$J30)) | D30: =IF($J30="","",INDEX(休憩マスタ!$B$5:$B$61,$J30)) | E30: =IF($J30="","",INDEX(休憩マスタ!$J$5:$J$61,$J30)) | F30: =IF($J30="","",INDEX(休憩マスタ!$F$5:$F$61,$J30)) | G30: =IF($J30="","",INDEX(休憩マスタ!$H$5:$H$61,$J30)) | J30: =IFERROR(MATCH(25,休憩マスタ!$I$5:$I$61,0),"")
A31: =IF($J31="","",INDEX(休憩マスタ!$C$5:$C$61,$J31)) | B31: =IF($J31="","",INDEX(休憩マスタ!$D$5:$D$61,$J31)) | C31: =IF($J31="","",INDEX(休憩マスタ!$E$5:$E$61,$J31)) | D31: =IF($J31="","",INDEX(休憩マスタ!$B$5:$B$61,$J31)) | E31: =IF($J31="","",INDEX(休憩マスタ!$J$5:$J$61,$J31)) | F31: =IF($J31="","",INDEX(休憩マスタ!$F$5:$F$61,$J31)) | G31: =IF($J31="","",INDEX(休憩マスタ!$H$5:$H$61,$J31)) | J31: =IFERROR(MATCH(26,休憩マスタ!$I$5:$I$61,0),"")
A32: =IF($J32="","",INDEX(休憩マスタ!$C$5:$C$61,$J32)) | B32: =IF($J32="","",INDEX(休憩マスタ!$D$5:$D$61,$J32)) | C32: =IF($J32="","",INDEX(休憩マスタ!$E$5:$E$61,$J32)) | D32: =IF($J32="","",INDEX(休憩マスタ!$B$5:$B$61,$J32)) | E32: =IF($J32="","",INDEX(休憩マスタ!$J$5:$J$61,$J32)) | F32: =IF($J32="","",INDEX(休憩マスタ!$F$5:$F$61,$J32)) | G32: =IF($J32="","",INDEX(休憩マスタ!$H$5:$H$61,$J32)) | J32: =IFERROR(MATCH(27,休憩マスタ!$I$5:$I$61,0),"")
A33: =IF($J33="","",INDEX(休憩マスタ!$C$5:$C$61,$J33)) | B33: =IF($J33="","",INDEX(休憩マスタ!$D$5:$D$61,$J33)) | C33: =IF($J33="","",INDEX(休憩マスタ!$E$5:$E$61,$J33)) | D33: =IF($J33="","",INDEX(休憩マスタ!$B$5:$B$61,$J33)) | E33: =IF($J33="","",INDEX(休憩マスタ!$J$5:$J$61,$J33)) | F33: =IF($J33="","",INDEX(休憩マスタ!$F$5:$F$61,$J33)) | G33: =IF($J33="","",INDEX(休憩マスタ!$H$5:$H$61,$J33)) | J33: =IFERROR(MATCH(28,休憩マスタ!$I$5:$I$61,0),"")
A34: =IF($J34="","",INDEX(休憩マスタ!$C$5:$C$61,$J34)) | B34: =IF($J34="","",INDEX(休憩マスタ!$D$5:$D$61,$J34)) | C34: =IF($J34="","",INDEX(休憩マスタ!$E$5:$E$61,$J34)) | D34: =IF($J34="","",INDEX(休憩マスタ!$B$5:$B$61,$J34)) | E34: =IF($J34="","",INDEX(休憩マスタ!$J$5:$J$61,$J34)) | F34: =IF($J34="","",INDEX(休憩マスタ!$F$5:$F$61,$J34)) | G34: =IF($J34="","",INDEX(休憩マスタ!$H$5:$H$61,$J34)) | J34: =IFERROR(MATCH(29,休憩マスタ!$I$5:$I$61,0),"")
A35: =IF($J35="","",INDEX(休憩マスタ!$C$5:$C$61,$J35)) | B35: =IF($J35="","",INDEX(休憩マスタ!$D$5:$D$61,$J35)) | C35: =IF($J35="","",INDEX(休憩マスタ!$E$5:$E$61,$J35)) | D35: =IF($J35="","",INDEX(休憩マスタ!$B$5:$B$61,$J35)) | E35: =IF($J35="","",INDEX(休憩マスタ!$J$5:$J$61,$J35)) | F35: =IF($J35="","",INDEX(休憩マスタ!$F$5:$F$61,$J35)) | G35: =IF($J35="","",INDEX(休憩マスタ!$H$5:$H$61,$J35)) | J35: =IFERROR(MATCH(30,休憩マスタ!$I$5:$I$61,0),"")
A36: =IF($J36="","",INDEX(休憩マスタ!$C$5:$C$61,$J36)) | B36: =IF($J36="","",INDEX(休憩マスタ!$D$5:$D$61,$J36)) | C36: =IF($J36="","",INDEX(休憩マスタ!$E$5:$E$61,$J36)) | D36: =IF($J36="","",INDEX(休憩マスタ!$B$5:$B$61,$J36)) | E36: =IF($J36="","",INDEX(休憩マスタ!$J$5:$J$61,$J36)) | F36: =IF($J36="","",INDEX(休憩マスタ!$F$5:$F$61,$J36)) | G36: =IF($J36="","",INDEX(休憩マスタ!$H$5:$H$61,$J36)) | J36: =IFERROR(MATCH(31,休憩マスタ!$I$5:$I$61,0),"")
A37: =IF($J37="","",INDEX(休憩マスタ!$C$5:$C$61,$J37)) | B37: =IF($J37="","",INDEX(休憩マスタ!$D$5:$D$61,$J37)) | C37: =IF($J37="","",INDEX(休憩マスタ!$E$5:$E$61,$J37)) | D37: =IF($J37="","",INDEX(休憩マスタ!$B$5:$B$61,$J37)) | E37: =IF($J37="","",INDEX(休憩マスタ!$J$5:$J$61,$J37)) | F37: =IF($J37="","",INDEX(休憩マスタ!$F$5:$F$61,$J37)) | G37: =IF($J37="","",INDEX(休憩マスタ!$H$5:$H$61,$J37)) | J37: =IFERROR(MATCH(32,休憩マスタ!$I$5:$I$61,0),"")
A38: =IF($J38="","",INDEX(休憩マスタ!$C$5:$C$61,$J38)) | B38: =IF($J38="","",INDEX(休憩マスタ!$D$5:$D$61,$J38)) | C38: =IF($J38="","",INDEX(休憩マスタ!$E$5:$E$61,$J38)) | D38: =IF($J38="","",INDEX(休憩マスタ!$B$5:$B$61,$J38)) | E38: =IF($J38="","",INDEX(休憩マスタ!$J$5:$J$61,$J38)) | F38: =IF($J38="","",INDEX(休憩マスタ!$F$5:$F$61,$J38)) | G38: =IF($J38="","",INDEX(休憩マスタ!$H$5:$H$61,$J38)) | J38: =IFERROR(MATCH(33,休憩マスタ!$I$5:$I$61,0),"")
A39: =IF($J39="","",INDEX(休憩マスタ!$C$5:$C$61,$J39)) | B39: =IF($J39="","",INDEX(休憩マスタ!$D$5:$D$61,$J39)) | C39: =IF($J39="","",INDEX(休憩マスタ!$E$5:$E$61,$J39)) | D39: =IF($J39="","",INDEX(休憩マスタ!$B$5:$B$61,$J39)) | E39: =IF($J39="","",INDEX(休憩マスタ!$J$5:$J$61,$J39)) | F39: =IF($J39="","",INDEX(休憩マスタ!$F$5:$F$61,$J39)) | G39: =IF($J39="","",INDEX(休憩マスタ!$H$5:$H$61,$J39)) | J39: =IFERROR(MATCH(34,休憩マスタ!$I$5:$I$61,0),"")
A40: =IF($J40="","",INDEX(休憩マスタ!$C$5:$C$61,$J40)) | B40: =IF($J40="","",INDEX(休憩マスタ!$D$5:$D$61,$J40)) | C40: =IF($J40="","",INDEX(休憩マスタ!$E$5:$E$61,$J40)) | D40: =IF($J40="","",INDEX(休憩マスタ!$B$5:$B$61,$J40)) | E40: =IF($J40="","",INDEX(休憩マスタ!$J$5:$J$61,$J40)) | F40: =IF($J40="","",INDEX(休憩マスタ!$F$5:$F$61,$J40)) | G40: =IF($J40="","",INDEX(休憩マスタ!$H$5:$H$61,$J40)) | J40: =IFERROR(MATCH(35,休憩マスタ!$I$5:$I$61,0),"")
A41: =IF($J41="","",INDEX(休憩マスタ!$C$5:$C$61,$J41)) | B41: =IF($J41="","",INDEX(休憩マスタ!$D$5:$D$61,$J41)) | C41: =IF($J41="","",INDEX(休憩マスタ!$E$5:$E$61,$J41)) | D41: =IF($J41="","",INDEX(休憩マスタ!$B$5:$B$61,$J41)) | E41: =IF($J41="","",INDEX(休憩マスタ!$J$5:$J$61,$J41)) | F41: =IF($J41="","",INDEX(休憩マスタ!$F$5:$F$61,$J41)) | G41: =IF($J41="","",INDEX(休憩マスタ!$H$5:$H$61,$J41)) | J41: =IFERROR(MATCH(36,休憩マスタ!$I$5:$I$61,0),"")
...

Sheet 行路_ロング
A1: 系統 | B1: ダイヤ | C1: 路線 | D1: 方向 | E1: 列車番号 | F1: 放送番号 | G1: 駅 | H1: 着発 | I1: 日跨ぎ | J1: 種別 | K1: 充当 | L1: 着時刻(秒) | M1: 発時刻(秒) | N1: 車内集札 | O1: 金庫 | P1: 後部要員 | Q1: 番線 | R1: 西院止まり | S1: 便乗表示列番 | T1: 退勤 | U1: 次休憩
A2: 1 | B2: 休日 | C2: 本線 | D2: 下り | E2: 0501 | F2: 0502 | G2: 西院 | H2: 発 | J2: 営業 | M2: 5:30:20
A3: 1 | B3: 休日 | C3: 本線 | D3: 下り | E3: 0501 | F3: 0502 | G3: 西大路三条 | H3: 発 | J3: 営業 | L3: 5:32:10 | M3: 5:32:25
A4: 1 | B4: 休日 | C4: 本線 | D4: 下り | E4: 0501 | F4: 0502 | G4: 山ノ内 | H4: 発 | J4: 営業 | L4: 5:34:20 | M4: 5:34:45
A5: 1 | B5: 休日 | C5: 本線 | D5: 下り | E5: 0501 | F5: 0502 | G5: 天神川 | H5: 発 | J5: 営業 | L5: 5:36:45 | M5: 5:37:10
A6: 1 | B6: 休日 | C6: 本線 | D6: 下り | E6: 0501 | F6: 0502 | G6: 蚕ノ社 | H6: 発 | J6: 営業 | L6: 5:38:00 | M6: 5:38:15
A7: 1 | B7: 休日 | C7: 本線 | D7: 下り | E7: 0501 | F7: 0502 | G7: 太秦広隆寺 | H7: 発 | J7: 営業 | L7: 5:39:35 | M7: 5:39:50
A8: 1 | B8: 休日 | C8: 本線 | D8: 下り | E8: 0501 | F8: 0502 | G8: 帷子ノ辻 | H8: 発 | J8: 営業 | L8: 5:41:50 | M8: 5:42:20 | N8: ○
A9: 1 | B9: 休日 | C9: 本線 | D9: 下り | E9: 0501 | F9: 0502 | G9: 有栖川 | H9: 発 | J9: 営業 | L9: 5:43:30 | M9: 5:43:45
A10: 1 | B10: 休日 | C10: 本線 | D10: 下り | E10: 0501 | F10: 0502 | G10: 車折 | H10: 発 | J10: 営業 | L10: 5:45:10 | M10: 5:45:25
A11: 1 | B11: 休日 | C11: 本線 | D11: 下り | E11: 0501 | F11: 0502 | G11: 鹿王院 | H11: 発 | J11: 営業 | L11: 5:46:20 | M11: 5:46:35
A12: 1 | B12: 休日 | C12: 本線 | D12: 下り | E12: 0501 | F12: 0502 | G12: 嵯峨 | H12: 発 | J12: 営業 | L12: 5:47:40 | M12: 5:47:55
A13: 1 | B13: 休日 | C13: 本線 | D13: 下り | E13: 0501 | F13: 0502 | G13: 嵐山 | H13: 着 | J13: 営業 | L13: 5:49:00 | N13: ○ | Q13: 1
A14: 1 | B14: 休日 | C14: 本線 | D14: 上り | E14: 0502 | F14: 0201 | G14: 嵐山 | H14: 発 | J14: 営業 | M14: 5:53:00 | Q14: 1
A15: 1 | B15: 休日 | C15: 本線 | D15: 上り | E15: 0502 | F15: 0201 | G15: 嵯峨 | H15: 発 | J15: 営業 | L15: 5:53:55 | M15: 5:54:20
A16: 1 | B16: 休日 | C16: 本線 | D16: 上り | E16: 0502 | F16: 0201 | G16: 鹿王院 | H16: 発 | J16: 営業 | L16: 5:55:25 | M16: 5:55:45
A17: 1 | B17: 休日 | C17: 本線 | D17: 上り | E17: 0502 | F17: 0201 | G17: 車折 | H17: 発 | J17: 営業 | L17: 5:56:40 | M17: 5:57:10
A18: 1 | B18: 休日 | C18: 本線 | D18: 上り | E18: 0502 | F18: 0201 | G18: 有栖川 | H18: 発 | J18: 営業 | L18: 5:58:35 | M18: 5:58:55
A19: 1 | B19: 休日 | C19: 本線 | D19: 上り | E19: 0502 | F19: 0201 | G19: 帷子ノ辻 | H19: 発 | J19: 営業 | L19: 6:00:10 | M19: 6:01:15 | N19: ○
A20: 1 | B20: 休日 | C20: 本線 | D20: 上り | E20: 0502 | F20: 0201 | G20: 太秦広隆寺 | H20: 発 | J20: 営業 | L20: 6:03:25 | M20: 6:03:45
A21: 1 | B21: 休日 | C21: 本線 | D21: 上り | E21: 0502 | F21: 0201 | G21: 蚕ノ社 | H21: 発 | J21: 営業 | L21: 6:05:00 | M21: 6:05:20
A22: 1 | B22: 休日 | C22: 本線 | D22: 上り | E22: 0502 | F22: 0201 | G22: 天神川 | H22: 発 | J22: 営業 | L22: 6:06:05 | M22: 6:06:50
A23: 1 | B23: 休日 | C23: 本線 | D23: 上り | E23: 0502 | F23: 0201 | G23: 山ノ内 | H23: 発 | J23: 営業 | L23: 6:08:40 | M23: 6:09:05
A24: 1 | B24: 休日 | C24: 本線 | D24: 上り | E24: 0502 | F24: 0201 | G24: 西大路三条 | H24: 発 | J24: 営業 | L24: 6:10:55 | M24: 6:11:15
A25: 1 | B25: 休日 | C25: 本線 | D25: 上り | E25: 0502 | F25: 0201 | G25: 西院 | H25: 発 | J25: 営業 | L25: 6:13:10 | M25: 6:14:05
A26: 1 | B26: 休日 | C26: 本線 | D26: 上り | E26: 0502 | F26: 0201 | G26: 四条大宮 | H26: 着 | J26: 営業 | L26: 6:17:00 | N26: ○ | Q26: 1
A27: 1 | B27: 休日 | C27: 本線 | D27: 下り | E27: 0605 | F27: 0102 | G27: 四条大宮 | H27: 発 | J27: 営業 | M27: 6:25:00 | Q27: 1
A28: 1 | B28: 休日 | C28: 本線 | D28: 下り | E28: 0605 | F28: 0102 | G28: 西院 | H28: 発 | J28: 営業 | L28: 6:27:50 | M28: 6:28:20
A29: 1 | B29: 休日 | C29: 本線 | D29: 下り | E29: 0605 | F29: 0102 | G29: 西大路三条 | H29: 発 | J29: 営業 | L29: 6:30:10 | M29: 6:30:25
A30: 1 | B30: 休日 | C30: 本線 | D30: 下り | E30: 0605 | F30: 0102 | G30: 山ノ内 | H30: 発 | J30: 営業 | L30: 6:32:20 | M30: 6:32:45
A31: 1 | B31: 休日 | C31: 本線 | D31: 下り | E31: 0605 | F31: 0102 | G31: 天神川 | H31: 発 | J31: 営業 | L31: 6:34:45 | M31: 6:35:10
A32: 1 | B32: 休日 | C32: 本線 | D32: 下り | E32: 0605 | F32: 0102 | G32: 蚕ノ社 | H32: 発 | J32: 営業 | L32: 6:36:00 | M32: 6:36:15
A33: 1 | B33: 休日 | C33: 本線 | D33: 下り | E33: 0605 | F33: 0102 | G33: 太秦広隆寺 | H33: 発 | J33: 営業 | L33: 6:37:35 | M33: 6:37:50
A34: 1 | B34: 休日 | C34: 本線 | D34: 下り | E34: 0605 | F34: 0102 | G34: 帷子ノ辻 | H34: 発 | J34: 営業 | L34: 6:39:50 | M34: 6:40:20 | N34: ○
A35: 1 | B35: 休日 | C35: 本線 | D35: 下り | E35: 0605 | F35: 0102 | G35: 有栖川 | H35: 発 | J35: 営業 | L35: 6:41:30 | M35: 6:41:45
A36: 1 | B36: 休日 | C36: 本線 | D36: 下り | E36: 0605 | F36: 0102 | G36: 車折 | H36: 発 | J36: 営業 | L36: 6:43:10 | M36: 6:43:25
A37: 1 | B37: 休日 | C37: 本線 | D37: 下り | E37: 0605 | F37: 0102 | G37: 鹿王院 | H37: 発 | J37: 営業 | L37: 6:44:20 | M37: 6:44:35
A38: 1 | B38: 休日 | C38: 本線 | D38: 下り | E38: 0605 | F38: 0102 | G38: 嵯峨 | H38: 発 | J38: 営業 | L38: 6:45:40 | M38: 6:45:55
A39: 1 | B39: 休日 | C39: 本線 | D39: 下り | E39: 0605 | F39: 0102 | G39: 嵐山 | H39: 着 | J39: 営業 | L39: 6:47:00 | N39: ○ | Q39: 1
A40: 1 | B40: 休日 | C40: 本線 | D40: 上り | E40: 0608 | F40: 2221 | G40: 嵐山 | H40: 発 | J40: 営業 | M40: 6:53:00 | Q40: 1
...

Sheet 休憩マスタ
A1: 休憩マスタ（事前計算済み）
A2: 休憩=系統内連続イベント間の空き。西院10分以上(本線)/帷子ノ辻26分以上(北野線)。嵐山・四条大宮・北野白梅町の折返除外。120分以上=中休勤務(退勤)。
A4: ダイヤ | B4: 系統 | C4: 開始 | D4: 終了 | E4: 所要分 | F4: 交代駅 | G4: 路線 | H4: 区分 | I4: 当日順位 | J4: 担当運転士
A5: 休日 | B5: 1 | C5: 08:26 | D5: 09:46 | E5: 80 | F5: 西院 | G5: 本線 | H5: 休憩 | I5: =IF(A5=当日早見表!$B$3,COUNTIF($A$5:$A5,当日早見表!$B$3),"") | J5: =IFERROR(INDEX(当日早見表!$B$7:$B$44,MATCH(B5&"系統",当日早見表!$A$7:$A$44,0)),"")
A6: 休日 | B6: 16 | C6: 08:44 | D6: 09:46 | E6: 62 | F6: 帷子ノ辻 | G6: 北野線 | H6: 休憩 | I6: =IF(A6=当日早見表!$B$3,COUNTIF($A$5:$A6,当日早見表!$B$3),"") | J6: =IFERROR(INDEX(当日早見表!$B$7:$B$44,MATCH(B6&"系統",当日早見表!$A$7:$A$44,0)),"")
A7: 休日 | B7: 3 | C7: 08:56 | D7: 10:16 | E7: 80 | F7: 西院 | G7: 本線 | H7: 休憩 | I7: =IF(A7=当日早見表!$B$3,COUNTIF($A$5:$A7,当日早見表!$B$3),"") | J7: =IFERROR(INDEX(当日早見表!$B$7:$B$44,MATCH(B7&"系統",当日早見表!$A$7:$A$44,0)),"")
A8: 休日 | B8: 17 | C8: 09:34 | D8: 10:36 | E8: 62 | F8: 帷子ノ辻 | G8: 北野線 | H8: 休憩 | I8: =IF(A8=当日早見表!$B$3,COUNTIF($A$5:$A8,当日早見表!$B$3),"") | J8: =IFERROR(INDEX(当日早見表!$B$7:$B$44,MATCH(B8&"系統",当日早見表!$A$7:$A$44,0)),"")
A9: 休日 | B9: 2 | C9: 09:46 | D9: 11:06 | E9: 80 | F9: 西院 | G9: 本線 | H9: 休憩 | I9: =IF(A9=当日早見表!$B$3,COUNTIF($A$5:$A9,当日早見表!$B$3),"") | J9: =IFERROR(INDEX(当日早見表!$B$7:$B$44,MATCH(B9&"系統",当日早見表!$A$7:$A$44,0)),"")
A10: 休日 | B10: 4 | C10: 10:16 | D10: 11:36 | E10: 80 | F10: 西院 | G10: 本線 | H10: 休憩 | I10: =IF(A10=当日早見表!$B$3,COUNTIF($A$5:$A10,当日早見表!$B$3),"") | J10: =IFERROR(INDEX(当日早見表!$B$7:$B$44,MATCH(B10&"系統",当日早見表!$A$7:$A$44,0)),"")
A11: 休日 | B11: 18 | C11: 10:24 | D11: 11:26 | E11: 62 | F11: 帷子ノ辻 | G11: 北野線 | H11: 休憩 | I11: =IF(A11=当日早見表!$B$3,COUNTIF($A$5:$A11,当日早見表!$B$3),"") | J11: =IFERROR(INDEX(当日早見表!$B$7:$B$44,MATCH(B11&"系統",当日早見表!$A$7:$A$44,0)),"")
A12: 休日 | B12: 6 | C12: 11:06 | D12: 12:26 | E12: 80 | F12: 西院 | G12: 本線 | H12: 休憩 | I12: =IF(A12=当日早見表!$B$3,COUNTIF($A$5:$A12,当日早見表!$B$3),"") | J12: =IFERROR(INDEX(当日早見表!$B$7:$B$44,MATCH(B12&"系統",当日早見表!$A$7:$A$44,0)),"")
A13: 休日 | B13: 19 | C13: 11:14 | D13: 12:16 | E13: 62 | F13: 帷子ノ辻 | G13: 北野線 | H13: 休憩 | I13: =IF(A13=当日早見表!$B$3,COUNTIF($A$5:$A13,当日早見表!$B$3),"") | J13: =IFERROR(INDEX(当日早見表!$B$7:$B$44,MATCH(B13&"系統",当日早見表!$A$7:$A$44,0)),"")
A14: 休日 | B14: 5 | C14: 11:36 | D14: 12:56 | E14: 80 | F14: 西院 | G14: 本線 | H14: 休憩 | I14: =IF(A14=当日早見表!$B$3,COUNTIF($A$5:$A14,当日早見表!$B$3),"") | J14: =IFERROR(INDEX(当日早見表!$B$7:$B$44,MATCH(B14&"系統",当日早見表!$A$7:$A$44,0)),"")
A15: 休日 | B15: 20 | C15: 12:04 | D15: 17:06 | E15: 302 | F15: 帷子ノ辻 | G15: 北野線 | H15: 中休勤務 | I15: =IF(A15=当日早見表!$B$3,COUNTIF($A$5:$A15,当日早見表!$B$3),"") | J15: =IFERROR(INDEX(当日早見表!$B$7:$B$44,MATCH(B15&"系統",当日早見表!$A$7:$A$44,0)),"")
A16: 休日 | B16: 8 | C16: 12:26 | D16: 17:36 | E16: 310 | F16: 西院 | G16: 本線 | H16: 中休勤務 | I16: =IF(A16=当日早見表!$B$3,COUNTIF($A$5:$A16,当日早見表!$B$3),"") | J16: =IFERROR(INDEX(当日早見表!$B$7:$B$44,MATCH(B16&"系統",当日早見表!$A$7:$A$44,0)),"")
... A61: 平日 | B61: 15 | C61: 22:06 | D61: 22:33 | E61: 27 | F61: 西院 | G61: 本線 | H61: 休憩 | I61: =IF(A61=当日早見表!$B$3,COUNTIF($A$5:$A61,当日早見表!$B$3),"") | J61: =IFERROR(INDEX(当日早見表!$B$7:$B$44,MATCH(B61&"系統",当日早見表!$A$7:$A$44,0)),"")

Sheet 駅マスタ
A1: 路線 | B1: 駅順 | C1: 駅名 | D1: 略号
A2: 本線 | B2: 1 | C2: 嵐山 | D2: 嵐
A3: 本線 | B3: 2 | C3: 嵯峨 | D3: 嵯
A4: 本線 | B4: 3 | C4: 鹿王院 | D4: 鹿
A5: 本線 | B5: 4 | C5: 車折 | D5: 車
A6: 本線 | B6: 5 | C6: 有栖川 | D6: 有
A7: 本線 | B7: 6 | C7: 帷子ノ辻 | D7: 帷
A8: 本線 | B8: 7 | C8: 太秦広隆寺 | D8: 太
A9: 本線 | B9: 8 | C9: 蚕ノ社 | D9: 蚕
A10: 本線 | B10: 9 | C10: 天神川 | D10: 天
A11: 本線 | B11: 10 | C11: 山ノ内 | D11: 山
A12: 本線 | B12: 11 | C12: 西大路三条 | D12: 三
A13: 本線 | B13: 12 | C13: 西院 | D13: 西
... A24: 北野線 | B24: 10 | C24: 帷子ノ辻 | D24: 帷

Sheet README
A1: 運転士 行路表 分析用.xlsx — データ辞書＆運用ガイド（説明不要レベル・全ツール共通） | B1: 嵐電(本線 嵐山↔四条大宮13駅／北野線 北野白梅町↔帷子ノ辻)の運転士担当データ。運転士表HTMLの出力仕様は『表示仕様_帷子到着表』シートに完全記載。
A2: 【シート一覧】
A3: 早見表_全期間 | B3: 日付×系統 の担当運転士表(2026-05〜)。ダイヤ区分(平日/休日)も保持。担当解決の正本。
A4: 行路_ロング | B4: 1行=1列車×1駅イベント(9744行・23列)。便・時刻(秒)・属性・各フラグの正本。下記列辞書参照。
A5: 出退勤マスタ | B5: 系統別の出勤/退勤時刻。中休勤務=系統8/9/20/21(2回出勤)。
A6: 休憩マスタ | B6: 系統別の休憩(開始/終了/所要分/交代駅/区分)。行路_ロング『次休憩』列の生成元。
A7: 駅マスタ | B7: 駅名・略号・路線内駅順。本線 嵐山(1)〜四条大宮(13)／北野線 帷子ノ辻〜北野白梅町。
A8: 祝日マスタ | B8: 祝日判定(休日ダイヤ)。
A9: 便乗_乗車便対応 | B9: 便乗便→乗車列車番号の対応。便乗の番線/運転時分継承・列番表示に使用。
A10: 当日早見表／当日休憩ビュー | B10: TODAY()連動の当日抽出ビュー(手動確認用)。生成器は使用しない。
A11: 表示仕様_帷子到着表 | B11: 運転士表HTML出力の完全仕様書(唯一の基準)。
A12: 【行路_ロング 列辞書（23列）】
A13: 系統 | B13: 行路(乗務員1日の仕業)番号。早見表でN系統→運転士名。
A14: ダイヤ | B14: 平日/休日。
A15: 路線 | B15: 本線/北野線(走行する物理線路で分類)。
A16: 方向 | B16: 上り/下り。本線:四条大宮行=上り/嵐山行=下り。北野:北野白梅町行=上り/帷子ノ辻行=下り。
A17: 列車番号 | B17: 列車(運行)番号。接頭『連』=連結運転、『回』=回送。便乗便は便乗ID。
A18: 放送番号 | B18: 車内放送番号。回送/便乗/空あり。
A19: 駅 | B19: 停車駅名(駅マスタ準拠)。
A20: 時刻 | B20: HH:MM(発時刻)。
A21: 到着時刻 | B21: 到着基準時刻(途中駅=発時刻/終着=着時刻/始発=空)。
A22: 着発 | B22: 着=終着(1列車に1つ)/発=その他(始発・途中)。
A23: 日跨ぎ | B23: ○=24時超で翌日に跨ぐ。
A24: 種別 | B24: 営業(834便,平日426・休日408)/便乗(32)/回送(19)。
... A36: 【結合キー】 | B36: 路線×ダイヤ×方向×列車番号(連/回除いた数字下4桁=core)。番線・運転時分は発着時刻表PDFと同キーで突合済。
A37: 【標準運用】
A38: ラスト | B38: 各乗務員の最終担当便=『退勤』列○。系統×列車番号一致でその便の全駅行に［ラスト］(全駅・時系列で判別)。
A39: 終着駅 | B39: 嵐山・四条大宮・北野白梅町=着発を1表に統合(gen_shu.py)。西院・帷子・途中駅=着/発別(gen_kt_chaku.py/gen_kt.py)。
A40: ファイル名 | B40: 頭に作成時刻 MMDD-HHMM(現在JST)。例 0617-2030_shijoomiya_着発.html。半角ローマ字駅名。
A41: 回答時JST | B41: チャット回答は毎回先頭に『📅 YYYY-MM-DD（曜日）HH:MM JST』。
A42: 高速化 | B42: 生成器は load_workbook(data_only=True,read_only=True)。行路_ロング・早見表のみ1回iter。
A43: 【既知の制約】
A44: 制約 | B44: ・時刻はhh:mm(秒は別列)。・25/27系統は出勤あり乗務便なし(枠のみ・正常)。・26系統は平日のみ短時間。・元データの出庫/下り交代/車内集札等の運用注記は別列化済。
A45: 運用ルール | B45: 運転士表(到着/発車)は依頼時に確認せず必ずHTMLで出力(基準時刻は指定なければ現在JST)。回答冒頭は📅 YYYY-MM-DD（曜）HH:MM JST形式。出力ファイル名は半角主体「MMDD-HHMM_ローマ字駅名_発.html/_着.html」(発着のみ日本語1字)。

Sheet 祝日マスタ
A1: 日付 | B1: 曜日 | C1: 区分 | D1: 名称
A2: 2026-05-05 | B2: 火 | C2: 休日 | D2: こどもの日
A3: 2026-05-06 | B3: 水 | C3: 休日 | D3: 憲法記念日 振替休日
A4: 2026-07-20 | B4: 月 | C4: 休日 | D4: 海の日
A5: 2026-08-11 | B5: 火 | C5: 休日 | D5: 山の日
A6: 2026-09-21 | B6: 月 | C6: 休日 | D6: 敬老の日
A7: 2026-09-22 | B7: 火 | C7: 休日 | D7: 国民の休日
A8: 2026-09-23 | B8: 水 | C8: 休日 | D8: 秋分の日
A9: 2026-10-12 | B9: 月 | C9: 休日 | D9: スポーツの日
A10: 2026-11-03 | B10: 火 | C10: 休日 | D10: 文化の日
A11: 2026-11-23 | B11: 月 | C11: 休日 | D11: 勤労感謝の日
A12: 2026-12-30 | B12: 水 | C12: 年末年始 | D12: （年末年始）
... A17: 2027-01-11 | B17: 月 | C17: 休日 | D17: 成人の日

Sheet 便乗_乗車便対応
A1: 便乗系統 | B1: 区分 | C1: 便乗ID | D1: 便乗発駅 | E1: 便乗発時刻 | F1: 便乗着駅 | G1: 便乗着時刻 | H1: 便乗方向 | I1: 乗車系統 | J1: 乗車列車番号 | K1: 乗車種別 | L1: 乗車発時刻 | M1: 乗車着時刻 | N1: 備考
A2: 16 | B2: 休日 | C2: 16系統②便乗 | D2: 帷子ノ辻 | E2: 13:41 | F2: 西院 | G2: 13:53 | H2: 上り | I2: 2 | J2: 連1308 | K2: 営業 | L2: 13:41 | M2: 13:54
A3: 16 | B3: 平日 | C3: 16系統⑤便乗 | D3: 帷子ノ辻 | E3: 13:51 | F3: 西院 | G3: 14:03 | H3: 上り | I3: 5 | J3: 1310 | K3: 営業 | L3: 13:51 | M3: 14:04
A4: 17 | B4: 休日 | C4: 17系統③便乗 | D4: 帷子ノ辻 | E4: 13:51 | F4: 西院 | G4: 14:03 | H4: 上り | I4: 3 | J4: 連1310 | K4: 営業 | L4: 13:51 | M4: 14:04
A5: 17 | B5: 平日 | C5: 17系統③便乗 | D5: 帷子ノ辻 | E5: 14:11 | F5: 西院 | G5: 14:23 | H5: 上り | I5: 3 | J5: 1402 | K5: 営業 | L5: 14:11 | M5: 14:24
A6: 18 | B6: 休日 | C6: 18系統②便乗 | D6: 西院 | E6: 06:43 | F6: 帷子ノ辻 | G6: 06:54 | H6: 下り | I6: 2 | J6: 0609 | K6: 営業 | L6: 06:43 | M6: 06:55
A7: 18 | B7: 休日 | C7: 18系統⑩便乗 | D7: 帷子ノ辻 | E7: 14:41 | F7: 西院 | G7: 14:53 | H7: 上り | I7: 10 | J7: 連1408 | K7: 営業 | L7: 14:41 | M7: 14:54
A8: 18 | B8: 平日 | C8: 18系統⑥便乗 | D8: 帷子ノ辻 | E8: 15:21 | F8: 西院 | G8: 15:33 | H8: 上り | I8: 6 | J8: 1504 | K8: 営業 | L8: 15:21 | M8: 15:34
A9: 19 | B9: 休日 | C9: 19系統⑫便乗 | D9: 帷子ノ辻 | E9: 15:31 | F9: 西院 | G9: 15:43 | H9: 上り | I9: 12 | J9: 連1506 | K9: 営業 | L9: 15:31 | M9: 15:44
A10: 19 | B10: 平日 | C10: 19系統⑱便乗 | D10: 西院 | E10: 06:40 | F10: 帷子ノ辻 | G10: 06:52 | H10: 下り | I10: 18 | J10: 回0691 | K10: 回送 | L10: 06:40 | M10: 06:51
A11: 19 | B11: 平日 | C11: 19系統⑬便乗 | D11: 帷子ノ辻 | E11: 15:53 | F11: 西院 | G11: 16:05 | H11: 上り | I11: 13 | J11: 連1510 | K11: 営業 | L11: 15:51 | M11: 16:04
A12: 20 | B12: 休日 | C12: 20系統⑤便乗 | D12: 西院 | E12: 08:36 | F12: 帷子ノ辻 | G12: 08:48 | H12: 下り | I12: 5 | J12: 0807 | K12: 営業 | L12: 08:36 | M12: 08:49
A13: 20 | B13: 休日 | C13: 20系統④便乗 | D13: 帷子ノ辻 | E13: 12:11 | F13: 西院 | G13: 12:23 | H13: 上り | I13: 4 | J13: 1202 | K13: 営業 | L13: 12:11 | M13: 12:24
... A31: 22 | B31: 休日 | C31: 22系統⑫便乗 | D31: 帷子ノ辻 | E31: 22:15 | F31: 西院 | G31: 22:26 | H31: 上り | I31: 12 | J31: 2202 | K31: 営業 | L31: 22:15 | M31: 22:27
A32: 13 | B32: 平日 | C32: 13系統⑧便乗 | D32: 西院 | E32: 20:23 | F32: 四条大宮 | G32: 20:26 | H32: 上り | I32: 8 | J32: 2002 | K32: 営業 | L32: 20:23 | M32: 20:26 | N32: 西院↔四条大宮(隣接2駅)の便乗。13系統乗務員が8系統電車2002に便乗
A33: 9 | B33: 平日 | C33: 9系統⑪便乗 | D33: 四条大宮 | E33: 20:53 | F33: 西院 | G33: 20:56 | H33: 下り | I33: 11 | J33: 2011 | K33: 営業 | L33: 20:53 | M33: 20:55 | N33: 西院↔四条大宮(隣接2駅)の便乗。9系統乗務員が11系統電車2011に便乗。西院着は指定20:56(乗車車2011実時刻20:55)

Sheet 表示仕様_帷子到着表
A1: 駅別 運転士表 — HTML出力 完全仕様書 v3（全駅・全ツール共通／本シート単独で同一HTMLを再現可能） | B1: 最終更新 2026-06-17。記憶・都度判断に依存せず、本シートと『運転士 行路表 分析用.xlsx』だけで誰でも同一の運転士表HTMLを生成できることを保証する。
A2: 【§0 大原則】
A3: 単一基準 | B3: 本シートが運転士表HTML出力の唯一かつ恒久の基準。レイアウト・色・フォント・付記・番線・ラスト・ファイル名・スクロール・JST表記まで本シートに従う。
A4: 自己完結HTML | B4: 外部CSS/JS/フォント/CDN/画像/localStorage 不使用。1ファイル完結。実行JSは読込時スクロールのみ。
A5: データ正本 | B5: 数値・担当・時刻・番線・各フラグは全て本xlsxに材料化済み（§3）。生成器は再計算せず列を読むだけ。
A6: 【§1 参照シート・結合キー】
A7: 担当運転士 | B7: 早見表_全期間：日付(行)×『N系統』列 で運転士名。『欠員①』等は『欠員』表記。休日前/休日後列は無視。
A8: 便・時刻・属性 | B8: 行路_ロング：1行=1列車×1駅イベント。ダイヤ(平日/休日)・路線・方向・駅でフィルタ。
A9: 結合キー | B9: 路線×ダイヤ×方向×列車番号(連/回接頭辞を除いたcore=数字下4桁)。番線・運転時分は発着時刻表PDFと同キーで突合済(秒時刻17,339件一致)。
A10: 補助 | B10: 出退勤マスタ(中休系統8/9/20/21)・休憩マスタ(次休憩列の生成元)・駅マスタ(駅順/略号)・祝日マスタ・便乗_乗車便対応。
A11: 【§2 行路_ロング 全列定義（23列・全て表示or用途を定義）】
A12: 系統 | B12: 担当解決キー。早見表でN系統→運転士。セル下段に『系統番号 運転士名』。
A13: ダイヤ | B13: 平日/休日。当日ダイヤで行抽出。画面非表示。
A14: 路線 | B14: 本線/北野線。列構成判定。
A15: 方向 | B15: 上り/下り。列振り分け。本線:四条大宮行=上り/嵐山行=下り。北野:北野白梅町行=上り/帷子ノ辻行=下り。
A16: 列車番号 | B16: セル上段『列{番号}』(#999 11px)。便乗は『便乗表示列番』に置換。
A17: 放送番号 | B17: 上段『放送{番号}』(#999 11px、列番の右にスペース)。回送/便乗/空は非表示。
A18: 駅 | B18: 対象駅フィルタ。画面非表示。
A19: 時刻 | B19: HH:MM。発車表/発列の表示時刻。
A20: 到着時刻 | B20: 到着基準(途中駅=発時刻/終着=着時刻/始発=空)。到着表/着列の表示時刻。
A21: 着発 | B21: 着(終着)/発(その他)。終着駅の着発分離・統合の着発列判定に使用。
A22: 日跨ぎ | B22: ○=24時超で翌日。時刻順序計算で+24h。
A23: 種別 | B23: 営業=無印/便乗=（便乗）/回送=【回送】を運転士名直後に付記。
... A34: 次休憩 | B34: 『→{駅} 休憩(開始〜終了)』(通常120分未満)または『→{駅} 退勤(中休…)』(120分以上)。セル下部別行。休憩=橙#e67e22/退勤=赤#d63031。
A35: 【§3 基準時刻・表示範囲・JST】
A36: 基準時刻 | B36: 既定=実行時の日本時間JST(Asia/Tokyo)。引数で任意日時指定可。UTC/固定値禁止。
A37: 表示範囲 | B37: 基準の前30分〜後120分(計150分)。範囲外は出力しない。
A38: ダイヤ確定 | B38: 早見表_全期間のダイヤ区分(曜日・祝日・年末年始判定済)で平日/休日を確定→行路_ロング該当ダイヤ。
A39: 回答時JST | B39: チャット回答は毎回先頭に『📅 YYYY-MM-DD（曜日）HH:MM JST』を必ず記載(運用ルール)。
A40: 【§4 ［ラスト］判定（系統別・方向別最終・駅ごと動的）】
A41: 定義 | B41: ［ラスト］=各系統がその駅を通る路線×方向ごとの最終営業便（その系統の最終発／最終着）。本線系統=上り最終・下り最終の両方／北野系統=上り最終・下り最終の両方。系統×路線×方向ごとに、その駅・当日ダイヤでの最終時刻便を動的判定。便乗・回送は対象外（営業便のみ）。〔2026-06-20改定：旧『本線=上り最終のみ』を上下両方へ拡張＝各乗務員の最終便（下り西院退勤便含む）を網羅。実装FINAL_RUNキー=(系統,路線,方向)。〕
A42: 判定範囲 | B42: 各系統について路線×方向ごとの最終営業便すべてに付す。グローバルな単一最終便ではなく系統×路線×方向ごと（複数系統・各方向が各々ラストを持つ）。その駅の表で、窓内にその系統のその方向の最終便が来ればラスト表示。
A43: 表記 | B43: 名前直後に赤#d63031太字11px『［ラスト］』。経過便なら薄字#b2bec3。回送/便乗は対象外。
A44: 【§5 番線表示（[ ]囲み・全駅）】
A45: 対象 | B45: 嵐山/四条大宮の2番線(着・発)、帷子ノ辻の北野線番線(3/4)、四条大宮の留置/誘導番線(1留/1誘)、帷子ノ辻北野線の留置/入庫/出庫番線(3留/4入/4出)。留/誘/留/入/出の付記がある便はその付記を保持して全駅(着発共)に表示。通常の番線1・北野白梅町・本線途中駅は非表示。付記番線(四条大宮・帷子)は『{駅名}{番線}→留置/入庫/出庫/誘導』形式で表示(着発の語は使わず→で示す)。
A46: 出典 | B46: 行路_ロング『番線』列(発着時刻表PDF由来)。本線上り番線は嵐山発番線・四条大宮着番線等、駅ごとに正しい値。
A47: 表記 | B47: セル下部に別行、濃灰#34495e太字11px、[ ]囲み。略号 嵐=嵐山/四=四条大宮/帷=帷子ノ辻。通常番線の例[四2着][帷4発](番線の語は付けず略号+番号+着発)。付記番線は『{駅名}{番線}→{留置/入庫/出庫/誘導}』形式=例[四1着→留置][四1着→誘導][帷子3→留置][帷子4→入庫][帷子4→出庫]。該当列車は全駅(着発共)の表に表示。複数は時刻順。
A48: 【§6 駅タイプ・列構成（自動判定）】
A49: 本線のみ(2列) | B49: 嵐山/嵯峨/鹿王院/車折/有栖川/太秦広隆寺/蚕ノ社/天神川/山ノ内/西大路三条/西院/四条大宮。列=本線上り(左)・本線下り(右)。
A50: 北野線のみ(2列) | B50: 北野白梅町/等持院/龍安寺/妙心寺/御室仁和寺/宇多野/鳴滝/常盤/撮影所前。列=北野上り・北野下り。
...
